Workbook

Sheet Inputs
A1: ZAN FINANCIAL MODEL النموذج المالي لزان
B2: Model Inputs & Assumptions | D2: المدخلات والافتراضات
A4: 1 GENERAL ASSUMPTIONS الافتراضات العامة
B5: Project Name | C5: ZAN Waterfront – Jazan
B6: Location | C6: Jazan, North Corniche
B7: Model Start Year | C7: 2026
B8: Projection Horizon (years) | C8: 50
B9: Currency | C9: SAR
A11: 2 RENT ASSUMPTIONS افتراضات الإيجار
B12: Annual Rent Escalation (%) | C12: 0.0075
B13: Flexible Block Efficiency % | C13: 0.85
B14: Flexible Block Lease Rate (SAR/m²) | C14: 700
B15: Flexible Block Cost/m² (SAR) | C15: 3500
A17: 3 LAND RENT إيجار الأرض
B18: Annual Land Rent (SAR) | C18: 6000000
B19: Escalation Every N Years | C19: 5
B20: Land Rent Escalation (%) | C20: 0.05
B21: Grace Period (years) | C21: 5
B22: Land Rent Term (years) | C22: 50
A24: 4 CAPEX ASSUMPTIONS افتراضات التكاليف
B25: Soft Cost (%) | C25: 0.1
B26: Contingency (%) | C26: 0.05
A28: 5 SCENARIO SELECTOR اختيار السيناريو
B29: Active Scenario | C29: Base Case
B30: Options: | C30: Base Case
C31: CAPEX +10%
C32: Rent -10%
C33: Delay +6 months
C34: Escalation +0.5%
C35: Escalation -0.5%
B37: CAPEX Multiplier (calculated) | C37: =IF(C29="CAPEX +10%",1.1,1) -> 1
B38: Rent Multiplier (calculated) | C38: =IF(C29="Rent -10%",0.9,1) -> 1
B39: Delay (months) | C39: =IF(C29="Delay +6 months",6,0) -> 0
B40: Escalation Adjustment | C40: =IF(C29="Escalation +0.5%",0.005,IF(C29="Escalation -0.5%",-0.005,0)) -> 0
B41: Effective Rent Escalation | C41: =C12+C40 -> 0.0075
A43: 6 PHASES & PHASING المراحل
B44: Phase / المرحلة | C44: Start Year Offset | D44: Phase Footprint | E44: Land Rent Alloc. %
B45: ZAN 1 | C45: 2 | D45: =SUMPRODUCT((Program!A4:A50=B45)*(Program!G4:G50)) -> 32498 | E45: =IF(D$60=0,0,D45/D$60) -> 0.33725962
B46: ZAN 2 | C46: 3 | D46: =SUMPRODUCT((Program!A4:A50=B46)*(Program!G4:G50)) -> 37115 | E46: =IF(D$60=0,0,D46/D$60) -> 0.38517419
B47: ZAN 3 | C47: 4 | D47: =SUMPRODUCT((Program!A4:A50=B47)*(Program!G4:G50)) -> 26746 | E47: =IF(D$60=0,0,D47/D$60) -> 0.27756618
...

Sheet Program
A1: ASSET PROGRAM TABLE جدول الأصول
A3: Phase المرحلة | B3: Category التصنيف | C3: Asset Name اسم الأصل | D3: Code الرمز | E3: Notes ملاحظات | F3: Plot Area مساحة القطعة | G3: Bldg Footprint مساحة الدور | H3: GFA إجمالي المساحات | I3: Rev Type نوع الإيراد | J3: Eff % الكفاءة | K3: Leasable Area المساحة التأجيرية | L3: Lease Rate إيجار المتر | M3: Op EBITDA إيراد تشغيلي | N3: Escalation % الزيادة السنوية | O3: Ramp Up Yrs سنوات النمو | P3: Stab Occ % إشغال مستقر | Q3: Cost/m² تكلفة المتر | R3: Constr Start بداية البناء | S3: Constr Duration مدة البناء (شهر) | T3: Total CAPEX إجمالي التكلفة | U3: Constr Start Yr سنة بداية البناء | V3: Revenue Start Yr سنة بداية الإيراد | W3: Base Revenue الإيراد الأساسي | X3: Ramp Target هدف النمو
A4: ZAN 1 | B4: Hospitality | C4: Hotel | D4: H | E4: Anchor (Hotel) | F4: 5133 | G4: 2072 | H4: 16577 | I4: Operating | J4: 0 | K4: =H4*J4 -> 0 | L4: 0 | M4: =Operating_PL!C44 -> 13901057 | N4: =Inputs!C41 -> 0.0075 | O4: 4 | P4: 1 | Q4: 8000 | R4: =IFERROR(VLOOKUP(A4,Inputs!B45:C59,2,FALSE())+ROUND(Inputs!C39/12,0),0) -> 2 | S4: 36 | T4: =H4*Q4*(1+Inputs!$C$25)*(1+Inputs!$C$26)*Inputs!$C$37 -> 153171480 | U4: =Inputs!$C$7+R4 -> 2028 | V4: =IF(S4=0,U4,U4+CEILING(S4/12,1)) -> 2031 | W4: =IF(I4="Lease",K4*L4,IF(I4="Operating",M4,0)) -> 13901057 | X4: =IF(I4="Lease",P4,1) -> 1
A5: ZAN 1 | B5: Retail | C5: Retail - Sport Complex | D5: S | F5: 6000 | G5: 6000 | H5: 6000 | I5: Lease | J5: 1 | K5: =H5*J5 -> 6000 | L5: 173 | M5: =IF(I5="Operating",0,0) -> 0 | N5: =Inputs!C41 -> 0.0075 | O5: 3 | P5: 0.9 | Q5: 240 | R5: =IFERROR(VLOOKUP(A5,Inputs!B45:C59,2,FALSE())+ROUND(Inputs!C39/12,0),0) -> 2 | S5: 6 | T5: =H5*Q5*(1+Inputs!$C$25)*(1+Inputs!$C$26)*Inputs!$C$37 -> 1663200 | U5: =Inputs!$C$7+R5 -> 2028 | V5: =IF(S5=0,U5,U5+CEILING(S5/12,1)) -> 2029 | W5: =IF(I5="Lease",K5*L5,IF(I5="Operating",M5,0)) -> 1038000 | X5: =IF(I5="Lease",P5,1) -> 0.9
A6: ZAN 1 | B6: Utilities | C6: Parking & Landscaping ZAN1 | D6: (N/A) | E6: Parking & Landscaping | F6: =0 -> 0 | G6: 0 | H6: =(Inputs!C63-Program!G34)*Inputs!E45 -> 69513.93 | I6: Lease | J6: 0 | K6: =H6*J6 -> 0 | L6: 0 | M6: =IF(I6="Operating",0,0) -> 0 | N6: =0 -> 0 | O6: 0 | P6: 0 | Q6: 500 | R6: 4 | S6: 12 | T6: =H6*Q6*(1+Inputs!$C$25)*(1+Inputs!$C$26)*Inputs!$C$37 -> 40144295 | U6: =Inputs!$C$7+R6 -> 2030 | V6: =IF(S6=0,U6,U6+CEILING(S6/12,1)) -> 2031 | W6: =IF(I6="Lease",K6*L6,IF(I6="Operating",M6,0)) -> 0 | X6: =IF(I6="Lease",P6,1) -> 0
A7: ZAN 1 | B7: Retail | C7: Fuel Station | D7: F | E7: Shared utility | F7: 6920 | G7: 3586 | H7: 3586 | I7: Lease | J7: 0.3 | K7: =H7*J7 -> 1075.8 | L7: 900 | M7: =IF(I7="Operating",0,0) -> 0 | N7: =Inputs!C41 -> 0.0075 | O7: 3 | P7: 0.9 | Q7: 1500 | R7: =IFERROR(VLOOKUP(A7,Inputs!B45:C59,2,FALSE())+ROUND(Inputs!C39/12,0),0) -> 2 | S7: 12 | T7: =H7*Q7*(1+Inputs!$C$25)*(1+Inputs!$C$26)*Inputs!$C$37 -> 6212745 | U7: =Inputs!$C$7+R7 -> 2028 | V7: =IF(S7=0,U7,U7+CEILING(S7/12,1)) -> 2029 | W7: =IF(I7="Lease",K7*L7,IF(I7="Operating",M7,0)) -> 968220 | X7: =IF(I7="Lease",P7,1) -> 0.9
A8: ZAN 1 | B8: Marina | C8: Marina Berths | D8: MAR | E8: Anchor | F8: 3000 | G8: 0 | H8: 2400 | I8: Operating | J8: 0 | K8: =H8*J8 -> 0 | L8: 0 | M8: =Operating_PL!C80 -> 1129330.6 | N8: =Inputs!C41 -> 0.0075 | O8: 4 | P8: 0.9 | Q8: 16000 | R8: 4 | S8: 12 | T8: =H8*Q8*(1+Inputs!$C$25)*(1+Inputs!$C$26)*Inputs!$C$37 -> 44352000 | U8: =Inputs!$C$7+R8 -> 2030 | V8: =IF(S8=0,U8,U8+CEILING(S8/12,1)) -> 2031 | W8: =IF(I8="Lease",K8*L8,IF(I8="Operating",M8,0)) -> 1129330.6 | X8: =IF(I8="Lease",P8,1) -> 1
A9: ZAN 1 | B9: Retail | C9: Marina Mall | D9: C1 | E9: Anchor (Mall) | F9: 28947 | G9: 20840 | H9: 31260 | I9: Lease | J9: 0.8 | K9: =H9*J9 -> 25008 | L9: 2100 | M9: =IF(I9="Operating",0,0) -> 0 | N9: =Inputs!C41 -> 0.0075 | O9: 3 | P9: 0.9 | Q9: 3900 | R9: =IFERROR(VLOOKUP(A9,Inputs!B45:C59,2,FALSE())+ROUND(Inputs!C39/12,0),0) -> 2 | S9: 30 | T9: =H9*Q9*(1+Inputs!$C$25)*(1+Inputs!$C$26)*Inputs!$C$37 -> 140810670 | U9: =Inputs!$C$7+R9 -> 2028 | V9: =IF(S9=0,U9,U9+CEILING(S9/12,1)) -> 2031 | W9: =IF(I9="Lease",K9*L9,IF(I9="Operating",M9,0)) -> 52516800 | X9: =IF(I9="Lease",P9,1) -> 0.9
A10: ZAN 2 | B10: Retail | C10: Seafront Mall | D10: C2 | E10: Supporting anchor | F10: 4718 | G10: 4511 | H10: 8918 | I10: Lease | J10: 0.9 | K10: =H10*J10 -> 8026.2 | L10: 2000 | M10: =IF(I10="Operating",0,0) -> 0 | N10: =Inputs!C41 -> 0.0075 | O10: 3 | P10: 0.9 | Q10: 3500 | R10: =IFERROR(VLOOKUP(A10,Inputs!B45:C59,2,FALSE())+ROUND(Inputs!C39/12,0),0) -> 3 | S10: 24 | T10: =H10*Q10*(1+Inputs!$C$25)*(1+Inputs!$C$26)*Inputs!$C$37 -> 36051015 | U10: =Inputs!$C$7+R10 -> 2029 | V10: =IF(S10=0,U10,U10+CEILING(S10/12,1)) -> 2031 | W10: =IF(I10="Lease",K10*L10,IF(I10="Operating",M10,0)) -> 16052400 | X10: =IF(I10="Lease",P10,1) -> 0.9
A11: ZAN 2 | B11: Office | C11: Flexible Block (Office) | D11: R1 | E11: Flexible | F11: 4781 | G11: 2367 | H11: 11168 | I11: Lease | J11: =Inputs!C13 -> 0.85 | K11: =H11*J11 -> 9492.8 | L11: 850 | M11: =IF(I11="Operating",0,0) -> 0 | N11: =Inputs!C41 -> 0.0075 | O11: 3 | P11: 0.9 | Q11: 2600 | R11: =IFERROR(VLOOKUP(A11,Inputs!B45:C59,2,FALSE())+ROUND(Inputs!C39/12,0),0) -> 3 | S11: 30 | T11: =H11*Q11*(1+Inputs!$C$25)*(1+Inputs!$C$26)*Inputs!$C$37 -> 33537504 | U11: =Inputs!$C$7+R11 -> 2029 | V11: =IF(S11=0,U11,U11+CEILING(S11/12,1)) -> 2032 | W11: =IF(I11="Lease",K11*L11,IF(I11="Operating",M11,0)) -> 8068880 | X11: =IF(I11="Lease",P11,1) -> 0.9
A12: ZAN 2 | B12: Hospitality | C12: Resort | D12: Resort | E12: Core resort | F12: 33000 | G12: 15877 | H12: 16296 | I12: Operating | J12: 0 | K12: =H12*J12 -> 0 | L12: 0 | M12: =Operating_PL!D44 -> 19398143 | N12: =Inputs!C41 -> 0.0075 | O12: 4 | P12: 0.9 | Q12: 10000 | R12: =IFERROR(VLOOKUP(A12,Inputs!B45:C59,2,FALSE())+ROUND(Inputs!C39/12,0),0) -> 3 | S12: 42 | T12: =H12*Q12*(1+Inputs!$C$25)*(1+Inputs!$C$26)*Inputs!$C$37 -> 188218800 | U12: =Inputs!$C$7+R12 -> 2029 | V12: =IF(S12=0,U12,U12+CEILING(S12/12,1)) -> 2033 | W12: =IF(I12="Lease",K12*L12,IF(I12="Operating",M12,0)) -> 19398143 | X12: =IF(I12="Lease",P12,1) -> 1
A13: ZAN 2 | B13: Retail | C13: Supermarket | D13: C4 | E13: Daily needs | F13: 2023 | G13: 2023 | H13: 4044 | I13: Lease | J13: 0.9 | K13: =H13*J13 -> 3639.6 | L13: 500 | M13: =IF(I13="Operating",0,0) -> 0 | N13: =Inputs!C41 -> 0.0075 | O13: 2 | P13: 0.9 | Q13: 1500 | R13: =IFERROR(VLOOKUP(A13,Inputs!B45:C59,2,FALSE())+ROUND(Inputs!C39/12,0),0) -> 3 | S13: 18 | T13: =H13*Q13*(1+Inputs!$C$25)*(1+Inputs!$C$26)*Inputs!$C$37 -> 7006230 | U13: =Inputs!$C$7+R13 -> 2029 | V13: =IF(S13=0,U13,U13+CEILING(S13/12,1)) -> 2031 | W13: =IF(I13="Lease",K13*L13,IF(I13="Operating",M13,0)) -> 1819800 | X13: =IF(I13="Lease",P13,1) -> 0.9
A14: ZAN 2 | B14: Retail | C14: Shops / Cafes | D14: C5 | E14: F&B support | F14: 7439 | G14: 1167 | H14: 1167 | I14: Lease | J14: 0.9 | K14: =H14*J14 -> 1050.3 | L14: 2000 | M14: =IF(I14="Operating",0,0) -> 0 | N14: =Inputs!C41 -> 0.0075 | O14: 2 | P14: 0.9 | Q14: 3000 | R14: =IFERROR(VLOOKUP(A14,Inputs!B45:C59,2,FALSE())+ROUND(Inputs!C39/12,0),0) -> 3 | S14: 18 | T14: =H14*Q14*(1+Inputs!$C$25)*(1+Inputs!$C$26)*Inputs!$C$37 -> 4043655 | U14: =Inputs!$C$7+R14 -> 2029 | V14: =IF(S14=0,U14,U14+CEILING(S14/12,1)) -> 2031 | W14: =IF(I14="Lease",K14*L14,IF(I14="Operating",M14,0)) -> 2100600 | X14: =IF(I14="Lease",P14,1) -> 0.9
A15: ZAN 2 | B15: Retail | C15: Shopping Area | D15: C3 | E15: Convenience | F15: 1567 | G15: 917 | H15: 3668 | I15: Lease | J15: 0.9 | K15: =H15*J15 -> 3301.2 | L15: 2000 | M15: =IF(I15="Operating",0,0) -> 0 | N15: =Inputs!C41 -> 0.0075 | O15: 2 | P15: 0.9 | Q15: 3000 | R15: =IFERROR(VLOOKUP(A15,Inputs!B45:C59,2,FALSE())+ROUND(Inputs!C39/12,0),0) -> 3 | S15: 18 | T15: =H15*Q15*(1+Inputs!$C$25)*(1+Inputs!$C$26)*Inputs!$C$37 -> 12709620 | U15: =Inputs!$C$7+R15 -> 2029 | V15: =IF(S15=0,U15,U15+CEILING(S15/12,1)) -> 2031 | W15: =IF(I15="Lease",K15*L15,IF(I15="Operating",M15,0)) -> 6602400 | X15: =IF(I15="Lease",P15,1) -> 0.9
A16: ZAN 2 | B16: Retail | C16: Shops / Cafes | D16: C10 | E16: F&B support | F16: 6990 | G16: 1167 | H16: 1167 | I16: Lease | J16: 0.9 | K16: =H16*J16 -> 1050.3 | L16: 2000 | M16: =IF(I16="Operating",0,0) -> 0 | N16: =Inputs!C41 -> 0.0075 | O16: 2 | P16: 0.9 | Q16: 3000 | R16: =IFERROR(VLOOKUP(A16,Inputs!B45:C59,2,FALSE())+ROUND(Inputs!C39/12,0),0) -> 3 | S16: 18 | T16: =H16*Q16*(1+Inputs!$C$25)*(1+Inputs!$C$26)*Inputs!$C$37 -> 4043655 | U16: =Inputs!$C$7+R16 -> 2029 | V16: =IF(S16=0,U16,U16+CEILING(S16/12,1)) -> 2031 | W16: =IF(I16="Lease",K16*L16,IF(I16="Operating",M16,0)) -> 2100600 | X16: =IF(I16="Lease",P16,1) -> 0.9
A17: ZAN 2 | B17: Utilities | C17: Parking & Landscaping ZAN2 | D17: (N/A) | E17: Parking & Landscaping | F17: =0 -> 0 | G17: 0 | H17: =(Inputs!C63-Program!G34)*Inputs!E46 -> 79389.793 | I17: Lease | J17: 0 | K17: =H17*J17 -> 0 | L17: 0 | M17: =IF(I17="Operating",0,0) -> 0 | N17: =0 -> 0 | O17: 0 | P17: 0 | Q17: 500 | R17: 4 | S17: 12 | T17: =H17*Q17*(1+Inputs!$C$25)*(1+Inputs!$C$26)*Inputs!$C$37 -> 45847606 | U17: =Inputs!$C$7+R17 -> 2030 | V17: =IF(S17=0,U17,U17+CEILING(S17/12,1)) -> 2031 | W17: =IF(I17="Lease",K17*L17,IF(I17="Operating",M17,0)) -> 0 | X17: =IF(I17="Lease",P17,1) -> 0
A18: ZAN 2 | B18: Office | C18: Office Block | D18: O1 | E18: Office | F18: 5497 | G18: 2710 | H18: 16429 | I18: Lease | J18: 0.9 | K18: =H18*J18 -> 14786.1 | L18: 900 | M18: =IF(I18="Operating",0,0) -> 0 | N18: =Inputs!C41 -> 0.0075 | O18: 3 | P18: 0.9 | Q18: 2600 | R18: =IFERROR(VLOOKUP(A18,Inputs!B45:C59,2,FALSE())+ROUND(Inputs!C39/12,0),0) -> 3 | S18: 30 | T18: =H18*Q18*(1+Inputs!$C$25)*(1+Inputs!$C$26)*Inputs!$C$37 -> 49336287 | U18: =Inputs!$C$7+R18 -> 2029 | V18: =IF(S18=0,U18,U18+CEILING(S18/12,1)) -> 2032 | W18: =IF(I18="Lease",K18*L18,IF(I18="Operating",M18,0)) -> 13307490 | X18: =IF(I18="Lease",P18,1) -> 0.9
A19: ZAN 2 | B19: Flexible | C19: Flexible Block (Residential) | D19: R3 | E19: Flexible | F19: 6664 | G19: 3066 | H19: 17153 | I19: Lease | J19: =Inputs!C13 -> 0.85 | K19: =H19*J19 -> 14580.05 | L19: 750 | M19: =IF(I19="Operating",0,0) -> 0 | N19: =Inputs!C41 -> 0.0075 | O19: 3 | P19: 0.9 | Q19: 3000 | R19: =IFERROR(VLOOKUP(A19,Inputs!B45:C59,2,FALSE())+ROUND(Inputs!C39/12,0),0) -> 3 | S19: 30 | T19: =H19*Q19*(1+Inputs!$C$25)*(1+Inputs!$C$26)*Inputs!$C$37 -> 59435145 | U19: =Inputs!$C$7+R19 -> 2029 | V19: =IF(S19=0,U19,U19+CEILING(S19/12,1)) -> 2032 | W19: =IF(I19="Lease",K19*L19,IF(I19="Operating",M19,0)) -> 10935038 | X19: =IF(I19="Lease",P19,1) -> 0.9
A20: ZAN 2 | B20: Flexible | C20: Flexible Block | D20: R4 | E20: Flexible | F20: 7558 | G20: 3310 | H20: 19316 | I20: Lease | J20: =Inputs!C13 -> 0.85 | K20: =H20*J20 -> 16418.6 | L20: 800 | M20: =IF(I20="Operating",0,0) -> 0 | N20: =Inputs!C41 -> 0.0075 | O20: 3 | P20: 0.9 | Q20: 2500 | R20: =IFERROR(VLOOKUP(A20,Inputs!B45:C59,2,FALSE())+ROUND(Inputs!C39/12,0),0) -> 3 | S20: 30 | T20: =H20*Q20*(1+Inputs!$C$25)*(1+Inputs!$C$26)*Inputs!$C$37 -> 55774950 | U20: =Inputs!$C$7+R20 -> 2029 | V20: =IF(S20=0,U20,U20+CEILING(S20/12,1)) -> 2032 | W20: =IF(I20="Lease",K20*L20,IF(I20="Operating",M20,0)) -> 13134880 | X20: =IF(I20="Lease",P20,1) -> 0.9
A21: ZAN 3 | B21: Residential | C21: Flexible Block | D21: R2 | E21: Flexible | F21: 6031 | G21: 2867 | H21: 14453 | I21: Lease | J21: =Inputs!C13 -> 0.85 | K21: =H21*J21 -> 12285.05 | L21: 800 | M21: =IF(I21="Operating",0,0) -> 0 | N21: =Inputs!C41 -> 0.0075 | O21: 3 | P21: 0.9 | Q21: 2500 | R21: =IFERROR(VLOOKUP(A21,Inputs!B45:C59,2,FALSE())+ROUND(Inputs!C39/12,0),0) -> 4 | S21: 30 | T21: =H21*Q21*(1+Inputs!$C$25)*(1+Inputs!$C$26)*Inputs!$C$37 -> 41733038 | U21: =Inputs!$C$7+R21 -> 2030 | V21: =IF(S21=0,U21,U21+CEILING(S21/12,1)) -> 2033 | W21: =IF(I21="Lease",K21*L21,IF(I21="Operating",M21,0)) -> 9828040 | X21: =IF(I21="Lease",P21,1) -> 0.9
A22: ZAN 3 | B22: Cultural | C22: Multi-Purpose Hall | D22: M | E22: Events/MICE | F22: 5376 | G22: 1624 | H22: 3248 | I22: Lease | J22: 1 | K22: =H22*J22 -> 3248 | L22: 900 | M22: =IF(I22="Operating",0,0) -> 0 | N22: =Inputs!C41 -> 0.0075 | O22: 3 | P22: 0.9 | Q22: 7500 | R22: =IFERROR(VLOOKUP(A22,Inputs!B45:C59,2,FALSE())+ROUND(Inputs!C39/12,0),0) -> 4 | S22: 24 | T22: =H22*Q22*(1+Inputs!$C$25)*(1+Inputs!$C$26)*Inputs!$C$37 -> 28135800 | U22: =Inputs!$C$7+R22 -> 2030 | V22: =IF(S22=0,U22,U22+CEILING(S22/12,1)) -> 2032 | W22: =IF(I22="Lease",K22*L22,IF(I22="Operating",M22,0)) -> 2923200 | X22: =IF(I22="Lease",P22,1) -> 0.9
A23: ZAN 3 | B23: Open Space | C23: Unallocated / Open Area | D23: Area | E23: Future plots | F23: 16642 | G23: 0 | H23: =F23*0.01 -> 166.42 | I23: Lease | J23: 1 | K23: =H23*J23 -> 166.42 | L23: 15000 | M23: =IF(I23="Operating",0,0) -> 0 | N23: =Inputs!C41 -> 0.0075 | O23: 1 | P23: 1 | Q23: 450 | R23: =IFERROR(VLOOKUP(A23,Inputs!B45:C59,2,FALSE())+ROUND(Inputs!C39/12,0),0) -> 4 | S23: 12 | T23: =H23*Q23*(1+Inputs!$C$25)*(1+Inputs!$C$26)*Inputs!$C$37 -> 86496.795 | U23: =Inputs!$C$7+R23 -> 2030 | V23: =IF(S23=0,U23,U23+CEILING(S23/12,1)) -> 2031 | W23: =IF(I23="Lease",K23*L23,IF(I23="Operating",M23,0)) -> 2496300 | X23: =IF(I23="Lease",P23,1) -> 1
A24: ZAN 3 | B24: Retail | C24: Shops / Cafes | D24: C6 | E24: Secondary | F24: 7121 | G24: 1005 | H24: 1005 | I24: Lease | J24: 0.9 | K24: =H24*J24 -> 904.5 | L24: 2200 | M24: =IF(I24="Operating",0,0) -> 0 | N24: =Inputs!C41 -> 0.0075 | O24: 2 | P24: 0.9 | Q24: 3000 | R24: =IFERROR(VLOOKUP(A24,Inputs!B45:C59,2,FALSE())+ROUND(Inputs!C39/12,0),0) -> 4 | S24: 18 | T24: =H24*Q24*(1+Inputs!$C$25)*(1+Inputs!$C$26)*Inputs!$C$37 -> 3482325 | U24: =Inputs!$C$7+R24 -> 2030 | V24: =IF(S24=0,U24,U24+CEILING(S24/12,1)) -> 2032 | W24: =IF(I24="Lease",K24*L24,IF(I24="Operating",M24,0)) -> 1989900 | X24: =IF(I24="Lease",P24,1) -> 0.9
A25: ZAN 3 | B25: Retail | C25: Small Market | D25: C8 | E25: Micro retail | F25: 616 | G25: 328 | H25: 314 | I25: Lease | J25: 0.9 | K25: =H25*J25 -> 282.6 | L25: 2000 | M25: =IF(I25="Operating",0,0) -> 0 | N25: =Inputs!C41 -> 0.0075 | O25: 2 | P25: 0.9 | Q25: 2000 | R25: =IFERROR(VLOOKUP(A25,Inputs!B45:C59,2,FALSE())+ROUND(Inputs!C39/12,0),0) -> 4 | S25: 18 | T25: =H25*Q25*(1+Inputs!$C$25)*(1+Inputs!$C$26)*Inputs!$C$37 -> 725340 | U25: =Inputs!$C$7+R25 -> 2030 | V25: =IF(S25=0,U25,U25+CEILING(S25/12,1)) -> 2032 | W25: =IF(I25="Lease",K25*L25,IF(I25="Operating",M25,0)) -> 565200 | X25: =IF(I25="Lease",P25,1) -> 0.9
A26: ZAN 3 | B26: Amenity | C26: Small Pavilions / Shops | D26: A1 | E26: Activation | F26: 15371 | G26: 4251 | H26: 3791 | I26: Lease | J26: 0.9 | K26: =H26*J26 -> 3411.9 | L26: 2200 | M26: =IF(I26="Operating",0,0) -> 0 | N26: =Inputs!C41 -> 0.0075 | O26: 2 | P26: 0.9 | Q26: 2000 | R26: =IFERROR(VLOOKUP(A26,Inputs!B45:C59,2,FALSE())+ROUND(Inputs!C39/12,0),0) -> 4 | S26: 18 | T26: =H26*Q26*(1+Inputs!$C$25)*(1+Inputs!$C$26)*Inputs!$C$37 -> 8757210 | U26: =Inputs!$C$7+R26 -> 2030 | V26: =IF(S26=0,U26,U26+CEILING(S26/12,1)) -> 2032 | W26: =IF(I26="Lease",K26*L26,IF(I26="Operating",M26,0)) -> 7506180 | X26: =IF(I26="Lease",P26,1) -> 0.9
A27: ZAN 3 | B27: Flexible | C27: Flexible Block | D27: R5 | E27: Flexible | F27: 6016 | G27: 4321 | H27: 25927 | I27: Lease | J27: =Inputs!C13 -> 0.85 | K27: =H27*J27 -> 22037.95 | L27: 800 | M27: =IF(I27="Operating",0,0) -> 0 | N27: =Inputs!C41 -> 0.0075 | O27: 3 | P27: 0.9 | Q27: 2800 | R27: =IFERROR(VLOOKUP(A27,Inputs!B45:C59,2,FALSE())+ROUND(Inputs!C39/12,0),0) -> 4 | S27: 30 | T27: =H27*Q27*(1+Inputs!$C$25)*(1+Inputs!$C$26)*Inputs!$C$37 -> 83847918 | U27: =Inputs!$C$7+R27 -> 2030 | V27: =IF(S27=0,U27,U27+CEILING(S27/12,1)) -> 2033 | W27: =IF(I27="Lease",K27*L27,IF(I27="Operating",M27,0)) -> 17630360 | X27: =IF(I27="Lease",P27,1) -> 0.9
A28: ZAN 3 | B28: Retail | C28: Shops / Cafes | D28: C7 | E28: Secondary | F28: 11401 | G28: 1310 | H28: 1310 | I28: Lease | J28: 0.9 | K28: =H28*J28 -> 1179 | L28: 2000 | M28: =IF(I28="Operating",0,0) -> 0 | N28: =Inputs!C41 -> 0.0075 | O28: 2 | P28: 0.9 | Q28: 3000 | R28: =IFERROR(VLOOKUP(A28,Inputs!B45:C59,2,FALSE())+ROUND(Inputs!C39/12,0),0) -> 4 | S28: 18 | T28: =H28*Q28*(1+Inputs!$C$25)*(1+Inputs!$C$26)*Inputs!$C$37 -> 4539150 | U28: =Inputs!$C$7+R28 -> 2030 | V28: =IF(S28=0,U28,U28+CEILING(S28/12,1)) -> 2032 | W28: =IF(I28="Lease",K28*L28,IF(I28="Operating",M28,0)) -> 2358000 | X28: =IF(I28="Lease",P28,1) -> 0.9
A29: ZAN 3 | B29: Retail | C29: Small Market | D29: C9 | E29: Micro retail | F29: 619 | G29: 362 | H29: 347 | I29: Lease | J29: 0.9 | K29: =H29*J29 -> 312.3 | L29: 2000 | M29: =IF(I29="Operating",0,0) -> 0 | N29: =Inputs!C41 -> 0.0075 | O29: 2 | P29: 0.9 | Q29: 2000 | R29: =IFERROR(VLOOKUP(A29,Inputs!B45:C59,2,FALSE())+ROUND(Inputs!C39/12,0),0) -> 4 | S29: 18 | T29: =H29*Q29*(1+Inputs!$C$25)*(1+Inputs!$C$26)*Inputs!$C$37 -> 801570 | U29: =Inputs!$C$7+R29 -> 2030 | V29: =IF(S29=0,U29,U29+CEILING(S29/12,1)) -> 2032 | W29: =IF(I29="Lease",K29*L29,IF(I29="Operating",M29,0)) -> 624600 | X29: =IF(I29="Lease",P29,1) -> 0.9
A30: ZAN 3 | B30: Residential | C30: Flexible Block (Branded) | D30: R6 | E30: Flexible | F30: 7411 | G30: 7430 | H30: 44218 | I30: Lease | J30: =Inputs!C13 -> 0.85 | K30: =H30*J30 -> 37585.3 | L30: 1200 | M30: =IF(I30="Operating",0,0) -> 0 | N30: =Inputs!C41 -> 0.0075 | O30: 3 | P30: 0.9 | Q30: 4500 | R30: =IFERROR(VLOOKUP(A30,Inputs!B45:C59,2,FALSE())+ROUND(Inputs!C39/12,0),0) -> 4 | S30: 30 | T30: =H30*Q30*(1+Inputs!$C$25)*(1+Inputs!$C$26)*Inputs!$C$37 -> 229823055 | U30: =Inputs!$C$7+R30 -> 2030 | V30: =IF(S30=0,U30,U30+CEILING(S30/12,1)) -> 2033 | W30: =IF(I30="Lease",K30*L30,IF(I30="Operating",M30,0)) -> 45102360 | X30: =IF(I30="Lease",P30,1) -> 0.9
A31: ZAN 3 | B31: Retail | C31: Flexible Block | D31: R7 | E31: Branded/Flex | F31: 3806 | G31: 1774 | H31: =G31*2.5 -> 4435 | I31: Lease | J31: =Inputs!C13 -> 0.85 | K31: =H31*J31 -> 3769.75 | L31: 800 | M31: =IF(I31="Operating",0,0) -> 0 | N31: =Inputs!C41 -> 0.0075 | O31: 3 | P31: 0.9 | Q31: 2500 | R31: =IFERROR(VLOOKUP(A31,Inputs!B45:C59,2,FALSE())+ROUND(Inputs!C39/12,0),0) -> 4 | S31: 30 | T31: =H31*Q31*(1+Inputs!$C$25)*(1+Inputs!$C$26)*Inputs!$C$37 -> 12806062 | U31: =Inputs!$C$7+R31 -> 2030 | V31: =IF(S31=0,U31,U31+CEILING(S31/12,1)) -> 2033 | W31: =IF(I31="Lease",K31*L31,IF(I31="Operating",M31,0)) -> 3015800 | X31: =IF(I31="Lease",P31,1) -> 0.9
A32: ZAN 3 | B32: Marina | C32: Yacht Club | D32: Yacht Club | E32: Marina anchor | F32: 3186 | G32: 1474 | H32: 2400 | I32: Lease | J32: 0.85 | K32: =H32*J32 -> 2040 | L32: 950 | M32: =IF(I32="Operating",0,0) -> 0 | N32: =Inputs!C41 -> 0.0075 | O32: 3 | P32: 0.9 | Q32: 6500 | R32: =IFERROR(VLOOKUP(A32,Inputs!B45:C59,2,FALSE())+ROUND(Inputs!C39/12,0),0) -> 4 | S32: 30 | T32: =H32*Q32*(1+Inputs!$C$25)*(1+Inputs!$C$26)*Inputs!$C$37 -> 18018000 | U32: =Inputs!$C$7+R32 -> 2030 | V32: =IF(S32=0,U32,U32+CEILING(S32/12,1)) -> 2033 | W32: =IF(I32="Lease",K32*L32,IF(I32="Operating",M32,0)) -> 1938000 | X32: =IF(I32="Lease",P32,1) -> 0.9
A33: ZAN 3 | B33: Utilities | C33: Parking & Landscaping ZAN3 | D33: (N/A) | E33: Parking & Landscaping | F33: =0 -> 0 | G33: 0 | H33: =(Inputs!C63-Program!G34)*Inputs!E47 -> 57210.277 | I33: Lease | J33: 0 | K33: =H33*J33 -> 0 | L33: 0 | M33: =IF(I33="Operating",0,0) -> 0 | N33: =0 -> 0 | O33: 0 | P33: 0 | Q33: 500 | R33: 4 | S33: 12 | T33: =H33*Q33*(1+Inputs!$C$25)*(1+Inputs!$C$26)*Inputs!$C$37 -> 33038935 | U33: =Inputs!$C$7+R33 -> 2030 | V33: =IF(S33=0,U33,U33+CEILING(S33/12,1)) -> 2031 | W33: =IF(I33="Lease",K33*L33,IF(I33="Operating",M33,0)) -> 0 | X33: =IF(I33="Lease",P33,1) -> 0
C34: TOTAL | F34: =SUM(F4:F33) -> 213833 | G34: =SUM(G4:G33) -> 96359 | H34: =SUM(H4:H33) -> 466877.42 | K34: =SUM(K4:K33) -> 191651.72 | T34: =SUM(T4:T33) -> 1.3481538e+09

Sheet CAPEX
A1: CAPEX SCHEDULE جدول توزيع التكاليف
A3: # | B3: Asset | C3: Phase | D3: Total | E3: =$C63+0 -> 2026 | F3: =$C63+1 -> 2027 | G3: =$C63+2 -> 2028 | H3: =$C63+3 -> 2029 | I3: =$C63+4 -> 2030 | J3: =$C63+5 -> 2031 | K3: =$C63+6 -> 2032 | L3: =$C63+7 -> 2033 | M3: =$C63+8 -> 2034 | N3: =$C63+9 -> 2035 | O3: =$C63+10 -> 2036 | P3: =$C63+11 -> 2037 | Q3: =$C63+12 -> 2038 | R3: =$C63+13 -> 2039 | S3: =$C63+14 -> 2040 | T3: =$C63+15 -> 2041 | U3: =$C63+16 -> 2042 | V3: =$C63+17 -> 2043 | W3: =$C63+18 -> 2044 | X3: =$C63+19 -> 2045 | Y3: =$C63+20 -> 2046 | Z3: =$C63+21 -> 2047 | AA3: =$C63+22 -> 2048 | AB3: =$C63+23 -> 2049 | AC3: =$C63+24 -> 2050 | AD3: =$C63+25 -> 2051 | AE3: =$C63+26 -> 2052 | AF3: =$C63+27 -> 2053 | AG3: =$C63+28 -> 2054 | AH3: =$C63+29 -> 2055 | AI3: =$C63+30 -> 2056 | AJ3: =$C63+31 -> 2057 | AK3: =$C63+32 -> 2058 | AL3: =$C63+33 -> 2059 | AM3: =$C63+34 -> 2060 | AN3: =$C63+35 -> 2061 | AO3: =$C63+36 -> 2062 | AP3: =$C63+37 -> 2063 | AQ3: =$C63+38 -> 2064 | AR3: =$C63+39 -> 2065 | AS3: =$C63+40 -> 2066 | AT3: =$C63+41 -> 2067 | AU3: =$C63+42 -> 2068 | AV3: =$C63+43 -> 2069 | AW3: =$C63+44 -> 2070 | AX3: =$C63+45 -> 2071 | AY3: =$C63+46 -> 2072 | AZ3: =$C63+47 -> 2073 | BA3: =$C63+48 -> 2074 | BB3: =$C63+49 -> 2075
A4: =A66 -> 1 | B4: =B66 -> Hotel | C4: =C66 -> ZAN 1 | D4: =SUM(E4:BB4) -> 153171480 | E4: =IF(OR(D66=0,E66=0,F66=0),0,IF(AND(E$3>=G66,E$3<H66),F66*MIN(12,E66-(E$3-G66)*12)/E66,0)) -> 0 | F4: =IF(OR(D66=0,E66=0,F66=0),0,IF(AND(F$3>=G66,F$3<H66),F66*MIN(12,E66-(F$3-G66)*12)/E66,0)) -> 0 | G4: =IF(OR(D66=0,E66=0,F66=0),0,IF(AND(G$3>=G66,G$3<H66),F66*MIN(12,E66-(G$3-G66)*12)/E66,0)) -> 51057160 | H4: =IF(OR(D66=0,E66=0,F66=0),0,IF(AND(H$3>=G66,H$3<H66),F66*MIN(12,E66-(H$3-G66)*12)/E66,0)) -> 51057160 | I4: =IF(OR(D66=0,E66=0,F66=0),0,IF(AND(I$3>=G66,I$3<H66),F66*MIN(12,E66-(I$3-G66)*12)/E66,0)) -> 51057160 | J4: =IF(OR(D66=0,E66=0,F66=0),0,IF(AND(J$3>=G66,J$3<H66),F66*MIN(12,E66-(J$3-G66)*12)/E66,0)) -> 0 | K4: =IF(OR(D66=0,E66=0,F66=0),0,IF(AND(K$3>=G66,K$3<H66),F66*MIN(12,E66-(K$3-G66)*12)/E66,0)) -> 0 | L4: =IF(OR(D66=0,E66=0,F66=0),0,IF(AND(L$3>=G66,L$3<H66),F66*MIN(12,E66-(L$3-G66)*12)/E66,0)) -> 0 | M4: =IF(OR(D66=0,E66=0,F66=0),0,IF(AND(M$3>=G66,M$3<H66),F66*MIN(12,E66-(M$3-G66)*12)/E66,0)) -> 0 | N4: =IF(OR(D66=0,E66=0,F66=0),0,IF(AND(N$3>=G66,N$3<H66),F66*MIN(12,E66-(N$3-G66)*12)/E66,0)) -> 0 | O4: =IF(OR(D66=0,E66=0,F66=0),0,IF(AND(O$3>=G66,O$3<H66),F66*MIN(12,E66-(O$3-G66)*12)/E66,0)) -> 0 | P4: =IF(OR(D66=0,E66=0,F66=0),0,IF(AND(P$3>=G66,P$3<H66),F66*MIN(12,E66-(P$3-G66)*12)/E66,0)) -> 0 | Q4: =IF(OR(D66=0,E66=0,F66=0),0,IF(AND(Q$3>=G66,Q$3<H66),F66*MIN(12,E66-(Q$3-G66)*12)/E66,0)) -> 0 | R4: =IF(OR(D66=0,E66=0,F66=0),0,IF(AND(R$3>=G66,R$3<H66),F66*MIN(12,E66-(R$3-G66)*12)/E66,0)) -> 0 | S4: =IF(OR(D66=0,E66=0,F66=0),0,IF(AND(S$3>=G66,S$3<H66),F66*MIN(12,E66-(S$3-G66)*12)/E66,0)) -> 0 | T4: =IF(OR(D66=0,E66=0,F66=0),0,IF(AND(T$3>=G66,T$3<H66),F66*MIN(12,E66-(T$3-G66)*12)/E66,0)) -> 0 | U4: =IF(OR(D66=0,E66=0,F66=0),0,IF(AND(U$3>=G66,U$3<H66),F66*MIN(12,E66-(U$3-G66)*12)/E66,0)) -> 0 | V4: =IF(OR(D66=0,E66=0,F66=0),0,IF(AND(V$3>=G66,V$3<H66),F66*MIN(12,E66-(V$3-G66)*12)/E66,0)) -> 0 | W4: =IF(OR(D66=0,E66=0,F66=0),0,IF(AND(W$3>=G66,W$3<H66),F66*MIN(12,E66-(W$3-G66)*12)/E66,0)) -> 0 | X4: =IF(OR(D66=0,E66=0,F66=0),0,IF(AND(X$3>=G66,X$3<H66),F66*MIN(12,E66-(X$3-G66)*12)/E66,0)) -> 0 | Y4: =IF(OR(D66=0,E66=0,F66=0),0,IF(AND(Y$3>=G66,Y$3<H66),F66*MIN(12,E66-(Y$3-G66)*12)/E66,0)) -> 0 | Z4: =IF(OR(D66=0,E66=0,F66=0),0,IF(AND(Z$3>=G66,Z$3<H66),F66*MIN(12,E66-(Z$3-G66)*12)/E66,0)) -> 0 | AA4: =IF(OR(D66=0,E66=0,F66=0),0,IF(AND(AA$3>=G66,AA$3<H66),F66*MIN(12,E66-(AA$3-G66)*12)/E66,0)) -> 0 | AB4: =IF(OR(D66=0,E66=0,F66=0),0,IF(AND(AB$3>=G66,AB$3<H66),F66*MIN(12,E66-(AB$3-G66)*12)/E66,0)) -> 0 | AC4: =IF(OR(D66=0,E66=0,F66=0),0,IF(AND(AC$3>=G66,AC$3<H66),F66*MIN(12,E66-(AC$3-G66)*12)/E66,0)) -> 0 | AD4: =IF(OR(D66=0,E66=0,F66=0),0,IF(AND(AD$3>=G66,AD$3<H66),F66*MIN(12,E66-(AD$3-G66)*12)/E66,0)) -> 0 | AE4: =IF(OR(D66=0,E66=0,F66=0),0,IF(AND(AE$3>=G66,AE$3<H66),F66*MIN(12,E66-(AE$3-G66)*12)/E66,0)) -> 0 | AF4: =IF(OR(D66=0,E66=0,F66=0),0,IF(AND(AF$3>=G66,AF$3<H66),F66*MIN(12,E66-(AF$3-G66)*12)/E66,0)) -> 0 | AG4: =IF(OR(D66=0,E66=0,F66=0),0,IF(AND(AG$3>=G66,AG$3<H66),F66*MIN(12,E66-(AG$3-G66)*12)/E66,0)) -> 0 | AH4: =IF(OR(D66=0,E66=0,F66=0),0,IF(AND(AH$3>=G66,AH$3<H66),F66*MIN(12,E66-(AH$3-G66)*12)/E66,0)) -> 0 | AI4: =IF(OR(D66=0,E66=0,F66=0),0,IF(AND(AI$3>=G66,AI$3<H66),F66*MIN(12,E66-(AI$3-G66)*12)/E66,0)) -> 0 | AJ4: =IF(OR(D66=0,E66=0,F66=0),0,IF(AND(AJ$3>=G66,AJ$3<H66),F66*MIN(12,E66-(AJ$3-G66)*12)/E66,0)) -> 0 | AK4: =IF(OR(D66=0,E66=0,F66=0),0,IF(AND(AK$3>=G66,AK$3<H66),F66*MIN(12,E66-(AK$3-G66)*12)/E66,0)) -> 0 | AL4: =IF(OR(D66=0,E66=0,F66=0),0,IF(AND(AL$3>=G66,AL$3<H66),F66*MIN(12,E66-(AL$3-G66)*12)/E66,0)) -> 0 | AM4: =IF(OR(D66=0,E66=0,F66=0),0,IF(AND(AM$3>=G66,AM$3<H66),F66*MIN(12,E66-(AM$3-G66)*12)/E66,0)) -> 0 | AN4: =IF(OR(D66=0,E66=0,F66=0),0,IF(AND(AN$3>=G66,AN$3<H66),F66*MIN(12,E66-(AN$3-G66)*12)/E66,0)) -> 0 | AO4: =IF(OR(D66=0,E66=0,F66=0),0,IF(AND(AO$3>=G66,AO$3<H66),F66*MIN(12,E66-(AO$3-G66)*12)/E66,0)) -> 0 | AP4: =IF(OR(D66=0,E66=0,F66=0),0,IF(AND(AP$3>=G66,AP$3<H66),F66*MIN(12,E66-(AP$3-G66)*12)/E66,0)) -> 0 | AQ4: =IF(OR(D66=0,E66=0,F66=0),0,IF(AND(AQ$3>=G66,AQ$3<H66),F66*MIN(12,E66-(AQ$3-G66)*12)/E66,0)) -> 0 | AR4: =IF(OR(D66=0,E66=0,F66=0),0,IF(AND(AR$3>=G66,AR$3<H66),F66*MIN(12,E66-(AR$3-G66)*12)/E66,0)) -> 0 | AS4: =IF(OR(D66=0,E66=0,F66=0),0,IF(AND(AS$3>=G66,AS$3<H66),F66*MIN(12,E66-(AS$3-G66)*12)/E66,0)) -> 0 | AT4: =IF(OR(D66=0,E66=0,F66=0),0,IF(AND(AT$3>=G66,AT$3<H66),F66*MIN(12,E66-(AT$3-G66)*12)/E66,0)) -> 0 | AU4: =IF(OR(D66=0,E66=0,F66=0),0,IF(AND(AU$3>=G66,AU$3<H66),F66*MIN(12,E66-(AU$3-G66)*12)/E66,0)) -> 0 | AV4: =IF(OR(D66=0,E66=0,F66=0),0,IF(AND(AV$3>=G66,AV$3<H66),F66*MIN(12,E66-(AV$3-G66)*12)/E66,0)) -> 0 | AW4: =IF(OR(D66=0,E66=0,F66=0),0,IF(AND(AW$3>=G66,AW$3<H66),F66*MIN(12,E66-(AW$3-G66)*12)/E66,0)) -> 0 | AX4: =IF(OR(D66=0,E66=0,F66=0),0,IF(AND(AX$3>=G66,AX$3<H66),F66*MIN(12,E66-(AX$3-G66)*12)/E66,0)) -> 0 | AY4: =IF(OR(D66=0,E66=0,F66=0),0,IF(AND(AY$3>=G66,AY$3<H66),F66*MIN(12,E66-(AY$3-G66)*12)/E66,0)) -> 0 | AZ4: =IF(OR(D66=0,E66=0,F66=0),0,IF(AND(AZ$3>=G66,AZ$3<H66),F66*MIN(12,E66-(AZ$3-G66)*12)/E66,0)) -> 0 | BA4: =IF(OR(D66=0,E66=0,F66=0),0,IF(AND(BA$3>=G66,BA$3<H66),F66*MIN(12,E66-(BA$3-G66)*12)/E66,0)) -> 0 | BB4: =IF(OR(D66=0,E66=0,F66=0),0,IF(AND(BB$3>=G66,BB$3<H66),F66*MIN(12,E66-(BB$3-G66)*12)/E66,0)) -> 0
A5: =A67 -> 2 | B5: =B67 -> Retail - Sport Complex | C5: =C67 -> ZAN 1 | D5: =SUM(E5:BB5) -> 1663200 | E5: =IF(OR(D67=0,E67=0,F67=0),0,IF(AND(E$3>=G67,E$3<H67),F67*MIN(12,E67-(E$3-G67)*12)/E67,0)) -> 0 | F5: =IF(OR(D67=0,E67=0,F67=0),0,IF(AND(F$3>=G67,F$3<H67),F67*MIN(12,E67-(F$3-G67)*12)/E67,0)) -> 0 | G5: =IF(OR(D67=0,E67=0,F67=0),0,IF(AND(G$3>=G67,G$3<H67),F67*MIN(12,E67-(G$3-G67)*12)/E67,0)) -> 1663200 | H5: =IF(OR(D67=0,E67=0,F67=0),0,IF(AND(H$3>=G67,H$3<H67),F67*MIN(12,E67-(H$3-G67)*12)/E67,0)) -> 0 | I5: =IF(OR(D67=0,E67=0,F67=0),0,IF(AND(I$3>=G67,I$3<H67),F67*MIN(12,E67-(I$3-G67)*12)/E67,0)) -> 0 | J5: =IF(OR(D67=0,E67=0,F67=0),0,IF(AND(J$3>=G67,J$3<H67),F67*MIN(12,E67-(J$3-G67)*12)/E67,0)) -> 0 | K5: =IF(OR(D67=0,E67=0,F67=0),0,IF(AND(K$3>=G67,K$3<H67),F67*MIN(12,E67-(K$3-G67)*12)/E67,0)) -> 0 | L5: =IF(OR(D67=0,E67=0,F67=0),0,IF(AND(L$3>=G67,L$3<H67),F67*MIN(12,E67-(L$3-G67)*12)/E67,0)) -> 0 | M5: =IF(OR(D67=0,E67=0,F67=0),0,IF(AND(M$3>=G67,M$3<H67),F67*MIN(12,E67-(M$3-G67)*12)/E67,0)) -> 0 | N5: =IF(OR(D67=0,E67=0,F67=0),0,IF(AND(N$3>=G67,N$3<H67),F67*MIN(12,E67-(N$3-G67)*12)/E67,0)) -> 0 | O5: =IF(OR(D67=0,E67=0,F67=0),0,IF(AND(O$3>=G67,O$3<H67),F67*MIN(12,E67-(O$3-G67)*12)/E67,0)) -> 0 | P5: =IF(OR(D67=0,E67=0,F67=0),0,IF(AND(P$3>=G67,P$3<H67),F67*MIN(12,E67-(P$3-G67)*12)/E67,0)) -> 0 | Q5: =IF(OR(D67=0,E67=0,F67=0),0,IF(AND(Q$3>=G67,Q$3<H67),F67*MIN(12,E67-(Q$3-G67)*12)/E67,0)) -> 0 | R5: =IF(OR(D67=0,E67=0,F67=0),0,IF(AND(R$3>=G67,R$3<H67),F67*MIN(12,E67-(R$3-G67)*12)/E67,0)) -> 0 | S5: =IF(OR(D67=0,E67=0,F67=0),0,IF(AND(S$3>=G67,S$3<H67),F67*MIN(12,E67-(S$3-G67)*12)/E67,0)) -> 0 | T5: =IF(OR(D67=0,E67=0,F67=0),0,IF(AND(T$3>=G67,T$3<H67),F67*MIN(12,E67-(T$3-G67)*12)/E67,0)) -> 0 | U5: =IF(OR(D67=0,E67=0,F67=0),0,IF(AND(U$3>=G67,U$3<H67),F67*MIN(12,E67-(U$3-G67)*12)/E67,0)) -> 0 | V5: =IF(OR(D67=0,E67=0,F67=0),0,IF(AND(V$3>=G67,V$3<H67),F67*MIN(12,E67-(V$3-G67)*12)/E67,0)) -> 0 | W5: =IF(OR(D67=0,E67=0,F67=0),0,IF(AND(W$3>=G67,W$3<H67),F67*MIN(12,E67-(W$3-G67)*12)/E67,0)) -> 0 | X5: =IF(OR(D67=0,E67=0,F67=0),0,IF(AND(X$3>=G67,X$3<H67),F67*MIN(12,E67-(X$3-G67)*12)/E67,0)) -> 0 | Y5: =IF(OR(D67=0,E67=0,F67=0),0,IF(AND(Y$3>=G67,Y$3<H67),F67*MIN(12,E67-(Y$3-G67)*12)/E67,0)) -> 0 | Z5: =IF(OR(D67=0,E67=0,F67=0),0,IF(AND(Z$3>=G67,Z$3<H67),F67*MIN(12,E67-(Z$3-G67)*12)/E67,0)) -> 0 | AA5: =IF(OR(D67=0,E67=0,F67=0),0,IF(AND(AA$3>=G67,AA$3<H67),F67*MIN(12,E67-(AA$3-G67)*12)/E67,0)) -> 0 | AB5: =IF(OR(D67=0,E67=0,F67=0),0,IF(AND(AB$3>=G67,AB$3<H67),F67*MIN(12,E67-(AB$3-G67)*12)/E67,0)) -> 0 | AC5: =IF(OR(D67=0,E67=0,F67=0),0,IF(AND(AC$3>=G67,AC$3<H67),F67*MIN(12,E67-(AC$3-G67)*12)/E67,0)) -> 0 | AD5: =IF(OR(D67=0,E67=0,F67=0),0,IF(AND(AD$3>=G67,AD$3<H67),F67*MIN(12,E67-(AD$3-G67)*12)/E67,0)) -> 0 | AE5: =IF(OR(D67=0,E67=0,F67=0),0,IF(AND(AE$3>=G67,AE$3<H67),F67*MIN(12,E67-(AE$3-G67)*12)/E67,0)) -> 0 | AF5: =IF(OR(D67=0,E67=0,F67=0),0,IF(AND(AF$3>=G67,AF$3<H67),F67*MIN(12,E67-(AF$3-G67)*12)/E67,0)) -> 0 | AG5: =IF(OR(D67=0,E67=0,F67=0),0,IF(AND(AG$3>=G67,AG$3<H67),F67*MIN(12,E67-(AG$3-G67)*12)/E67,0)) -> 0 | AH5: =IF(OR(D67=0,E67=0,F67=0),0,IF(AND(AH$3>=G67,AH$3<H67),F67*MIN(12,E67-(AH$3-G67)*12)/E67,0)) -> 0 | AI5: =IF(OR(D67=0,E67=0,F67=0),0,IF(AND(AI$3>=G67,AI$3<H67),F67*MIN(12,E67-(AI$3-G67)*12)/E67,0)) -> 0 | AJ5: =IF(OR(D67=0,E67=0,F67=0),0,IF(AND(AJ$3>=G67,AJ$3<H67),F67*MIN(12,E67-(AJ$3-G67)*12)/E67,0)) -> 0 | AK5: =IF(OR(D67=0,E67=0,F67=0),0,IF(AND(AK$3>=G67,AK$3<H67),F67*MIN(12,E67-(AK$3-G67)*12)/E67,0)) -> 0 | AL5: =IF(OR(D67=0,E67=0,F67=0),0,IF(AND(AL$3>=G67,AL$3<H67),F67*MIN(12,E67-(AL$3-G67)*12)/E67,0)) -> 0 | AM5: =IF(OR(D67=0,E67=0,F67=0),0,IF(AND(AM$3>=G67,AM$3<H67),F67*MIN(12,E67-(AM$3-G67)*12)/E67,0)) -> 0 | AN5: =IF(OR(D67=0,E67=0,F67=0),0,IF(AND(AN$3>=G67,AN$3<H67),F67*MIN(12,E67-(AN$3-G67)*12)/E67,0)) -> 0 | AO5: =IF(OR(D67=0,E67=0,F67=0),0,IF(AND(AO$3>=G67,AO$3<H67),F67*MIN(12,E67-(AO$3-G67)*12)/E67,0)) -> 0 | AP5: =IF(OR(D67=0,E67=0,F67=0),0,IF(AND(AP$3>=G67,AP$3<H67),F67*MIN(12,E67-(AP$3-G67)*12)/E67,0)) -> 0 | AQ5: =IF(OR(D67=0,E67=0,F67=0),0,IF(AND(AQ$3>=G67,AQ$3<H67),F67*MIN(12,E67-(AQ$3-G67)*12)/E67,0)) -> 0 | AR5: =IF(OR(D67=0,E67=0,F67=0),0,IF(AND(AR$3>=G67,AR$3<H67),F67*MIN(12,E67-(AR$3-G67)*12)/E67,0)) -> 0 | AS5: =IF(OR(D67=0,E67=0,F67=0),0,IF(AND(AS$3>=G67,AS$3<H67),F67*MIN(12,E67-(AS$3-G67)*12)/E67,0)) -> 0 | AT5: =IF(OR(D67=0,E67=0,F67=0),0,IF(AND(AT$3>=G67,AT$3<H67),F67*MIN(12,E67-(AT$3-G67)*12)/E67,0)) -> 0 | AU5: =IF(OR(D67=0,E67=0,F67=0),0,IF(AND(AU$3>=G67,AU$3<H67),F67*MIN(12,E67-(AU$3-G67)*12)/E67,0)) -> 0 | AV5: =IF(OR(D67=0,E67=0,F67=0),0,IF(AND(AV$3>=G67,AV$3<H67),F67*MIN(12,E67-(AV$3-G67)*12)/E67,0)) -> 0 | AW5: =IF(OR(D67=0,E67=0,F67=0),0,IF(AND(AW$3>=G67,AW$3<H67),F67*MIN(12,E67-(AW$3-G67)*12)/E67,0)) -> 0 | AX5: =IF(OR(D67=0,E67=0,F67=0),0,IF(AND(AX$3>=G67,AX$3<H67),F67*MIN(12,E67-(AX$3-G67)*12)/E67,0)) -> 0 | AY5: =IF(OR(D67=0,E67=0,F67=0),0,IF(AND(AY$3>=G67,AY$3<H67),F67*MIN(12,E67-(AY$3-G67)*12)/E67,0)) -> 0 | AZ5: =IF(OR(D67=0,E67=0,F67=0),0,IF(AND(AZ$3>=G67,AZ$3<H67),F67*MIN(12,E67-(AZ$3-G67)*12)/E67,0)) -> 0 | BA5: =IF(OR(D67=0,E67=0,F67=0),0,IF(AND(BA$3>=G67,BA$3<H67),F67*MIN(12,E67-(BA$3-G67)*12)/E67,0)) -> 0 | BB5: =IF(OR(D67=0,E67=0,F67=0),0,IF(AND(BB$3>=G67,BB$3<H67),F67*MIN(12,E67-(BB$3-G67)*12)/E67,0)) -> 0
A6: =A68 -> 3 | B6: =B68 -> Parking & Landscaping ZAN1 | C6: =C68 -> ZAN 1 | D6: =SUM(E6:BB6) -> 40144295 | E6: =IF(OR(D68=0,E68=0,F68=0),0,IF(AND(E$3>=G68,E$3<H68),F68*MIN(12,E68-(E$3-G68)*12)/E68,0)) -> 0 | F6: =IF(OR(D68=0,E68=0,F68=0),0,IF(AND(F$3>=G68,F$3<H68),F68*MIN(12,E68-(F$3-G68)*12)/E68,0)) -> 0 | G6: =IF(OR(D68=0,E68=0,F68=0),0,IF(AND(G$3>=G68,G$3<H68),F68*MIN(12,E68-(G$3-G68)*12)/E68,0)) -> 0 | H6: =IF(OR(D68=0,E68=0,F68=0),0,IF(AND(H$3>=G68,H$3<H68),F68*MIN(12,E68-(H$3-G68)*12)/E68,0)) -> 0 | I6: =IF(OR(D68=0,E68=0,F68=0),0,IF(AND(I$3>=G68,I$3<H68),F68*MIN(12,E68-(I$3-G68)*12)/E68,0)) -> 40144295 | J6: =IF(OR(D68=0,E68=0,F68=0),0,IF(AND(J$3>=G68,J$3<H68),F68*MIN(12,E68-(J$3-G68)*12)/E68,0)) -> 0 | K6: =IF(OR(D68=0,E68=0,F68=0),0,IF(AND(K$3>=G68,K$3<H68),F68*MIN(12,E68-(K$3-G68)*12)/E68,0)) -> 0 | L6: =IF(OR(D68=0,E68=0,F68=0),0,IF(AND(L$3>=G68,L$3<H68),F68*MIN(12,E68-(L$3-G68)*12)/E68,0)) -> 0 | M6: =IF(OR(D68=0,E68=0,F68=0),0,IF(AND(M$3>=G68,M$3<H68),F68*MIN(12,E68-(M$3-G68)*12)/E68,0)) -> 0 | N6: =IF(OR(D68=0,E68=0,F68=0),0,IF(AND(N$3>=G68,N$3<H68),F68*MIN(12,E68-(N$3-G68)*12)/E68,0)) -> 0 | O6: =IF(OR(D68=0,E68=0,F68=0),0,IF(AND(O$3>=G68,O$3<H68),F68*MIN(12,E68-(O$3-G68)*12)/E68,0)) -> 0 | P6: =IF(OR(D68=0,E68=0,F68=0),0,IF(AND(P$3>=G68,P$3<H68),F68*MIN(12,E68-(P$3-G68)*12)/E68,0)) -> 0 | Q6: =IF(OR(D68=0,E68=0,F68=0),0,IF(AND(Q$3>=G68,Q$3<H68),F68*MIN(12,E68-(Q$3-G68)*12)/E68,0)) -> 0 | R6: =IF(OR(D68=0,E68=0,F68=0),0,IF(AND(R$3>=G68,R$3<H68),F68*MIN(12,E68-(R$3-G68)*12)/E68,0)) -> 0 | S6: =IF(OR(D68=0,E68=0,F68=0),0,IF(AND(S$3>=G68,S$3<H68),F68*MIN(12,E68-(S$3-G68)*12)/E68,0)) -> 0 | T6: =IF(OR(D68=0,E68=0,F68=0),0,IF(AND(T$3>=G68,T$3<H68),F68*MIN(12,E68-(T$3-G68)*12)/E68,0)) -> 0 | U6: =IF(OR(D68=0,E68=0,F68=0),0,IF(AND(U$3>=G68,U$3<H68),F68*MIN(12,E68-(U$3-G68)*12)/E68,0)) -> 0 | V6: =IF(OR(D68=0,E68=0,F68=0),0,IF(AND(V$3>=G68,V$3<H68),F68*MIN(12,E68-(V$3-G68)*12)/E68,0)) -> 0 | W6: =IF(OR(D68=0,E68=0,F68=0),0,IF(AND(W$3>=G68,W$3<H68),F68*MIN(12,E68-(W$3-G68)*12)/E68,0)) -> 0 | X6: =IF(OR(D68=0,E68=0,F68=0),0,IF(AND(X$3>=G68,X$3<H68),F68*MIN(12,E68-(X$3-G68)*12)/E68,0)) -> 0 | Y6: =IF(OR(D68=0,E68=0,F68=0),0,IF(AND(Y$3>=G68,Y$3<H68),F68*MIN(12,E68-(Y$3-G68)*12)/E68,0)) -> 0 | Z6: =IF(OR(D68=0,E68=0,F68=0),0,IF(AND(Z$3>=G68,Z$3<H68),F68*MIN(12,E68-(Z$3-G68)*12)/E68,0)) -> 0 | AA6: =IF(OR(D68=0,E68=0,F68=0),0,IF(AND(AA$3>=G68,AA$3<H68),F68*MIN(12,E68-(AA$3-G68)*12)/E68,0)) -> 0 | AB6: =IF(OR(D68=0,E68=0,F68=0),0,IF(AND(AB$3>=G68,AB$3<H68),F68*MIN(12,E68-(AB$3-G68)*12)/E68,0)) -> 0 | AC6: =IF(OR(D68=0,E68=0,F68=0),0,IF(AND(AC$3>=G68,AC$3<H68),F68*MIN(12,E68-(AC$3-G68)*12)/E68,0)) -> 0 | AD6: =IF(OR(D68=0,E68=0,F68=0),0,IF(AND(AD$3>=G68,AD$3<H68),F68*MIN(12,E68-(AD$3-G68)*12)/E68,0)) -> 0 | AE6: =IF(OR(D68=0,E68=0,F68=0),0,IF(AND(AE$3>=G68,AE$3<H68),F68*MIN(12,E68-(AE$3-G68)*12)/E68,0)) -> 0 | AF6: =IF(OR(D68=0,E68=0,F68=0),0,IF(AND(AF$3>=G68,AF$3<H68),F68*MIN(12,E68-(AF$3-G68)*12)/E68,0)) -> 0 | AG6: =IF(OR(D68=0,E68=0,F68=0),0,IF(AND(AG$3>=G68,AG$3<H68),F68*MIN(12,E68-(AG$3-G68)*12)/E68,0)) -> 0 | AH6: =IF(OR(D68=0,E68=0,F68=0),0,IF(AND(AH$3>=G68,AH$3<H68),F68*MIN(12,E68-(AH$3-G68)*12)/E68,0)) -> 0 | AI6: =IF(OR(D68=0,E68=0,F68=0),0,IF(AND(AI$3>=G68,AI$3<H68),F68*MIN(12,E68-(AI$3-G68)*12)/E68,0)) -> 0 | AJ6: =IF(OR(D68=0,E68=0,F68=0),0,IF(AND(AJ$3>=G68,AJ$3<H68),F68*MIN(12,E68-(AJ$3-G68)*12)/E68,0)) -> 0 | AK6: =IF(OR(D68=0,E68=0,F68=0),0,IF(AND(AK$3>=G68,AK$3<H68),F68*MIN(12,E68-(AK$3-G68)*12)/E68,0)) -> 0 | AL6: =IF(OR(D68=0,E68=0,F68=0),0,IF(AND(AL$3>=G68,AL$3<H68),F68*MIN(12,E68-(AL$3-G68)*12)/E68,0)) -> 0 | AM6: =IF(OR(D68=0,E68=0,F68=0),0,IF(AND(AM$3>=G68,AM$3<H68),F68*MIN(12,E68-(AM$3-G68)*12)/E68,0)) -> 0 | AN6: =IF(OR(D68=0,E68=0,F68=0),0,IF(AND(AN$3>=G68,AN$3<H68),F68*MIN(12,E68-(AN$3-G68)*12)/E68,0)) -> 0 | AO6: =IF(OR(D68=0,E68=0,F68=0),0,IF(AND(AO$3>=G68,AO$3<H68),F68*MIN(12,E68-(AO$3-G68)*12)/E68,0)) -> 0 | AP6: =IF(OR(D68=0,E68=0,F68=0),0,IF(AND(AP$3>=G68,AP$3<H68),F68*MIN(12,E68-(AP$3-G68)*12)/E68,0)) -> 0 | AQ6: =IF(OR(D68=0,E68=0,F68=0),0,IF(AND(AQ$3>=G68,AQ$3<H68),F68*MIN(12,E68-(AQ$3-G68)*12)/E68,0)) -> 0 | AR6: =IF(OR(D68=0,E68=0,F68=0),0,IF(AND(AR$3>=G68,AR$3<H68),F68*MIN(12,E68-(AR$3-G68)*12)/E68,0)) -> 0 | AS6: =IF(OR(D68=0,E68=0,F68=0),0,IF(AND(AS$3>=G68,AS$3<H68),F68*MIN(12,E68-(AS$3-G68)*12)/E68,0)) -> 0 | AT6: =IF(OR(D68=0,E68=0,F68=0),0,IF(AND(AT$3>=G68,AT$3<H68),F68*MIN(12,E68-(AT$3-G68)*12)/E68,0)) -> 0 | AU6: =IF(OR(D68=0,E68=0,F68=0),0,IF(AND(AU$3>=G68,AU$3<H68),F68*MIN(12,E68-(AU$3-G68)*12)/E68,0)) -> 0 | AV6: =IF(OR(D68=0,E68=0,F68=0),0,IF(AND(AV$3>=G68,AV$3<H68),F68*MIN(12,E68-(AV$3-G68)*12)/E68,0)) -> 0 | AW6: =IF(OR(D68=0,E68=0,F68=0),0,IF(AND(AW$3>=G68,AW$3<H68),F68*MIN(12,E68-(AW$3-G68)*12)/E68,0)) -> 0 | AX6: =IF(OR(D68=0,E68=0,F68=0),0,IF(AND(AX$3>=G68,AX$3<H68),F68*MIN(12,E68-(AX$3-G68)*12)/E68,0)) -> 0 | AY6: =IF(OR(D68=0,E68=0,F68=0),0,IF(AND(AY$3>=G68,AY$3<H68),F68*MIN(12,E68-(AY$3-G68)*12)/E68,0)) -> 0 | AZ6: =IF(OR(D68=0,E68=0,F68=0),0,IF(AND(AZ$3>=G68,AZ$3<H68),F68*MIN(12,E68-(AZ$3-G68)*12)/E68,0)) -> 0 | BA6: =IF(OR(D68=0,E68=0,F68=0),0,IF(AND(BA$3>=G68,BA$3<H68),F68*MIN(12,E68-(BA$3-G68)*12)/E68,0)) -> 0 | BB6: =IF(OR(D68=0,E68=0,F68=0),0,IF(AND(BB$3>=G68,BB$3<H68),F68*MIN(12,E68-(BB$3-G68)*12)/E68,0)) -> 0
A7: =A69 -> 4 | B7: =B69 -> Fuel Station | C7: =C69 -> ZAN 1 | D7: =SUM(E7:BB7) -> 6212745 | E7: =IF(OR(D69=0,E69=0,F69=0),0,IF(AND(E$3>=G69,E$3<H69),F69*MIN(12,E69-(E$3-G69)*12)/E69,0)) -> 0 | F7: =IF(OR(D69=0,E69=0,F69=0),0,IF(AND(F$3>=G69,F$3<H69),F69*MIN(12,E69-(F$3-G69)*12)/E69,0)) -> 0 | G7: =IF(OR(D69=0,E69=0,F69=0),0,IF(AND(G$3>=G69,G$3<H69),F69*MIN(12,E69-(G$3-G69)*12)/E69,0)) -> 6212745 | H7: =IF(OR(D69=0,E69=0,F69=0),0,IF(AND(H$3>=G69,H$3<H69),F69*MIN(12,E69-(H$3-G69)*12)/E69,0)) -> 0 | I7: =IF(OR(D69=0,E69=0,F69=0),0,IF(AND(I$3>=G69,I$3<H69),F69*MIN(12,E69-(I$3-G69)*12)/E69,0)) -> 0 | J7: =IF(OR(D69=0,E69=0,F69=0),0,IF(AND(J$3>=G69,J$3<H69),F69*MIN(12,E69-(J$3-G69)*12)/E69,0)) -> 0 | K7: =IF(OR(D69=0,E69=0,F69=0),0,IF(AND(K$3>=G69,K$3<H69),F69*MIN(12,E69-(K$3-G69)*12)/E69,0)) -> 0 | L7: =IF(OR(D69=0,E69=0,F69=0),0,IF(AND(L$3>=G69,L$3<H69),F69*MIN(12,E69-(L$3-G69)*12)/E69,0)) -> 0 | M7: =IF(OR(D69=0,E69=0,F69=0),0,IF(AND(M$3>=G69,M$3<H69),F69*MIN(12,E69-(M$3-G69)*12)/E69,0)) -> 0 | N7: =IF(OR(D69=0,E69=0,F69=0),0,IF(AND(N$3>=G69,N$3<H69),F69*MIN(12,E69-(N$3-G69)*12)/E69,0)) -> 0 | O7: =IF(OR(D69=0,E69=0,F69=0),0,IF(AND(O$3>=G69,O$3<H69),F69*MIN(12,E69-(O$3-G69)*12)/E69,0)) -> 0 | P7: =IF(OR(D69=0,E69=0,F69=0),0,IF(AND(P$3>=G69,P$3<H69),F69*MIN(12,E69-(P$3-G69)*12)/E69,0)) -> 0 | Q7: =IF(OR(D69=0,E69=0,F69=0),0,IF(AND(Q$3>=G69,Q$3<H69),F69*MIN(12,E69-(Q$3-G69)*12)/E69,0)) -> 0 | R7: =IF(OR(D69=0,E69=0,F69=0),0,IF(AND(R$3>=G69,R$3<H69),F69*MIN(12,E69-(R$3-G69)*12)/E69,0)) -> 0 | S7: =IF(OR(D69=0,E69=0,F69=0),0,IF(AND(S$3>=G69,S$3<H69),F69*MIN(12,E69-(S$3-G69)*12)/E69,0)) -> 0 | T7: =IF(OR(D69=0,E69=0,F69=0),0,IF(AND(T$3>=G69,T$3<H69),F69*MIN(12,E69-(T$3-G69)*12)/E69,0)) -> 0 | U7: =IF(OR(D69=0,E69=0,F69=0),0,IF(AND(U$3>=G69,U$3<H69),F69*MIN(12,E69-(U$3-G69)*12)/E69,0)) -> 0 | V7: =IF(OR(D69=0,E69=0,F69=0),0,IF(AND(V$3>=G69,V$3<H69),F69*MIN(12,E69-(V$3-G69)*12)/E69,0)) -> 0 | W7: =IF(OR(D69=0,E69=0,F69=0),0,IF(AND(W$3>=G69,W$3<H69),F69*MIN(12,E69-(W$3-G69)*12)/E69,0)) -> 0 | X7: =IF(OR(D69=0,E69=0,F69=0),0,IF(AND(X$3>=G69,X$3<H69),F69*MIN(12,E69-(X$3-G69)*12)/E69,0)) -> 0 | Y7: =IF(OR(D69=0,E69=0,F69=0),0,IF(AND(Y$3>=G69,Y$3<H69),F69*MIN(12,E69-(Y$3-G69)*12)/E69,0)) -> 0 | Z7: =IF(OR(D69=0,E69=0,F69=0),0,IF(AND(Z$3>=G69,Z$3<H69),F69*MIN(12,E69-(Z$3-G69)*12)/E69,0)) -> 0 | AA7: =IF(OR(D69=0,E69=0,F69=0),0,IF(AND(AA$3>=G69,AA$3<H69),F69*MIN(12,E69-(AA$3-G69)*12)/E69,0)) -> 0 | AB7: =IF(OR(D69=0,E69=0,F69=0),0,IF(AND(AB$3>=G69,AB$3<H69),F69*MIN(12,E69-(AB$3-G69)*12)/E69,0)) -> 0 | AC7: =IF(OR(D69=0,E69=0,F69=0),0,IF(AND(AC$3>=G69,AC$3<H69),F69*MIN(12,E69-(AC$3-G69)*12)/E69,0)) -> 0 | AD7: =IF(OR(D69=0,E69=0,F69=0),0,IF(AND(AD$3>=G69,AD$3<H69),F69*MIN(12,E69-(AD$3-G69)*12)/E69,0)) -> 0 | AE7: =IF(OR(D69=0,E69=0,F69=0),0,IF(AND(AE$3>=G69,AE$3<H69),F69*MIN(12,E69-(AE$3-G69)*12)/E69,0)) -> 0 | AF7: =IF(OR(D69=0,E69=0,F69=0),0,IF(AND(AF$3>=G69,AF$3<H69),F69*MIN(12,E69-(AF$3-G69)*12)/E69,0)) -> 0 | AG7: =IF(OR(D69=0,E69=0,F69=0),0,IF(AND(AG$3>=G69,AG$3<H69),F69*MIN(12,E69-(AG$3-G69)*12)/E69,0)) -> 0 | AH7: =IF(OR(D69=0,E69=0,F69=0),0,IF(AND(AH$3>=G69,AH$3<H69),F69*MIN(12,E69-(AH$3-G69)*12)/E69,0)) -> 0 | AI7: =IF(OR(D69=0,E69=0,F69=0),0,IF(AND(AI$3>=G69,AI$3<H69),F69*MIN(12,E69-(AI$3-G69)*12)/E69,0)) -> 0 | AJ7: =IF(OR(D69=0,E69=0,F69=0),0,IF(AND(AJ$3>=G69,AJ$3<H69),F69*MIN(12,E69-(AJ$3-G69)*12)/E69,0)) -> 0 | AK7: =IF(OR(D69=0,E69=0,F69=0),0,IF(AND(AK$3>=G69,AK$3<H69),F69*MIN(12,E69-(AK$3-G69)*12)/E69,0)) -> 0 | AL7: =IF(OR(D69=0,E69=0,F69=0),0,IF(AND(AL$3>=G69,AL$3<H69),F69*MIN(12,E69-(AL$3-G69)*12)/E69,0)) -> 0 | AM7: =IF(OR(D69=0,E69=0,F69=0),0,IF(AND(AM$3>=G69,AM$3<H69),F69*MIN(12,E69-(AM$3-G69)*12)/E69,0)) -> 0 | AN7: =IF(OR(D69=0,E69=0,F69=0),0,IF(AND(AN$3>=G69,AN$3<H69),F69*MIN(12,E69-(AN$3-G69)*12)/E69,0)) -> 0 | AO7: =IF(OR(D69=0,E69=0,F69=0),0,IF(AND(AO$3>=G69,AO$3<H69),F69*MIN(12,E69-(AO$3-G69)*12)/E69,0)) -> 0 | AP7: =IF(OR(D69=0,E69=0,F69=0),0,IF(AND(AP$3>=G69,AP$3<H69),F69*MIN(12,E69-(AP$3-G69)*12)/E69,0)) -> 0 | AQ7: =IF(OR(D69=0,E69=0,F69=0),0,IF(AND(AQ$3>=G69,AQ$3<H69),F69*MIN(12,E69-(AQ$3-G69)*12)/E69,0)) -> 0 | AR7: =IF(OR(D69=0,E69=0,F69=0),0,IF(AND(AR$3>=G69,AR$3<H69),F69*MIN(12,E69-(AR$3-G69)*12)/E69,0)) -> 0 | AS7: =IF(OR(D69=0,E69=0,F69=0),0,IF(AND(AS$3>=G69,AS$3<H69),F69*MIN(12,E69-(AS$3-G69)*12)/E69,0)) -> 0 | AT7: =IF(OR(D69=0,E69=0,F69=0),0,IF(AND(AT$3>=G69,AT$3<H69),F69*MIN(12,E69-(AT$3-G69)*12)/E69,0)) -> 0 | AU7: =IF(OR(D69=0,E69=0,F69=0),0,IF(AND(AU$3>=G69,AU$3<H69),F69*MIN(12,E69-(AU$3-G69)*12)/E69,0)) -> 0 | AV7: =IF(OR(D69=0,E69=0,F69=0),0,IF(AND(AV$3>=G69,AV$3<H69),F69*MIN(12,E69-(AV$3-G69)*12)/E69,0)) -> 0 | AW7: =IF(OR(D69=0,E69=0,F69=0),0,IF(AND(AW$3>=G69,AW$3<H69),F69*MIN(12,E69-(AW$3-G69)*12)/E69,0)) -> 0 | AX7: =IF(OR(D69=0,E69=0,F69=0),0,IF(AND(AX$3>=G69,AX$3<H69),F69*MIN(12,E69-(AX$3-G69)*12)/E69,0)) -> 0 | AY7: =IF(OR(D69=0,E69=0,F69=0),0,IF(AND(AY$3>=G69,AY$3<H69),F69*MIN(12,E69-(AY$3-G69)*12)/E69,0)) -> 0 | AZ7: =IF(OR(D69=0,E69=0,F69=0),0,IF(AND(AZ$3>=G69,AZ$3<H69),F69*MIN(12,E69-(AZ$3-G69)*12)/E69,0)) -> 0 | BA7: =IF(OR(D69=0,E69=0,F69=0),0,IF(AND(BA$3>=G69,BA$3<H69),F69*MIN(12,E69-(BA$3-G69)*12)/E69,0)) -> 0 | BB7: =IF(OR(D69=0,E69=0,F69=0),0,IF(AND(BB$3>=G69,BB$3<H69),F69*MIN(12,E69-(BB$3-G69)*12)/E69,0)) -> 0
A8: =A70 -> 5 | B8: =B70 -> Marina Berths | C8: =C70 -> ZAN 1 | D8: =SUM(E8:BB8) -> 44352000 | E8: =IF(OR(D70=0,E70=0,F70=0),0,IF(AND(E$3>=G70,E$3<H70),F70*MIN(12,E70-(E$3-G70)*12)/E70,0)) -> 0 | F8: =IF(OR(D70=0,E70=0,F70=0),0,IF(AND(F$3>=G70,F$3<H70),F70*MIN(12,E70-(F$3-G70)*12)/E70,0)) -> 0 | G8: =IF(OR(D70=0,E70=0,F70=0),0,IF(AND(G$3>=G70,G$3<H70),F70*MIN(12,E70-(G$3-G70)*12)/E70,0)) -> 0 | H8: =IF(OR(D70=0,E70=0,F70=0),0,IF(AND(H$3>=G70,H$3<H70),F70*MIN(12,E70-(H$3-G70)*12)/E70,0)) -> 0 | I8: =IF(OR(D70=0,E70=0,F70=0),0,IF(AND(I$3>=G70,I$3<H70),F70*MIN(12,E70-(I$3-G70)*12)/E70,0)) -> 44352000 | J8: =IF(OR(D70=0,E70=0,F70=0),0,IF(AND(J$3>=G70,J$3<H70),F70*MIN(12,E70-(J$3-G70)*12)/E70,0)) -> 0 | K8: =IF(OR(D70=0,E70=0,F70=0),0,IF(AND(K$3>=G70,K$3<H70),F70*MIN(12,E70-(K$3-G70)*12)/E70,0)) -> 0 | L8: =IF(OR(D70=0,E70=0,F70=0),0,IF(AND(L$3>=G70,L$3<H70),F70*MIN(12,E70-(L$3-G70)*12)/E70,0)) -> 0 | M8: =IF(OR(D70=0,E70=0,F70=0),0,IF(AND(M$3>=G70,M$3<H70),F70*MIN(12,E70-(M$3-G70)*12)/E70,0)) -> 0 | N8: =IF(OR(D70=0,E70=0,F70=0),0,IF(AND(N$3>=G70,N$3<H70),F70*MIN(12,E70-(N$3-G70)*12)/E70,0)) -> 0 | O8: =IF(OR(D70=0,E70=0,F70=0),0,IF(AND(O$3>=G70,O$3<H70),F70*MIN(12,E70-(O$3-G70)*12)/E70,0)) -> 0 | P8: =IF(OR(D70=0,E70=0,F70=0),0,IF(AND(P$3>=G70,P$3<H70),F70*MIN(12,E70-(P$3-G70)*12)/E70,0)) -> 0 | Q8: =IF(OR(D70=0,E70=0,F70=0),0,IF(AND(Q$3>=G70,Q$3<H70),F70*MIN(12,E70-(Q$3-G70)*12)/E70,0)) -> 0 | R8: =IF(OR(D70=0,E70=0,F70=0),0,IF(AND(R$3>=G70,R$3<H70),F70*MIN(12,E70-(R$3-G70)*12)/E70,0)) -> 0 | S8: =IF(OR(D70=0,E70=0,F70=0),0,IF(AND(S$3>=G70,S$3<H70),F70*MIN(12,E70-(S$3-G70)*12)/E70,0)) -> 0 | T8: =IF(OR(D70=0,E70=0,F70=0),0,IF(AND(T$3>=G70,T$3<H70),F70*MIN(12,E70-(T$3-G70)*12)/E70,0)) -> 0 | U8: =IF(OR(D70=0,E70=0,F70=0),0,IF(AND(U$3>=G70,U$3<H70),F70*MIN(12,E70-(U$3-G70)*12)/E70,0)) -> 0 | V8: =IF(OR(D70=0,E70=0,F70=0),0,IF(AND(V$3>=G70,V$3<H70),F70*MIN(12,E70-(V$3-G70)*12)/E70,0)) -> 0 | W8: =IF(OR(D70=0,E70=0,F70=0),0,IF(AND(W$3>=G70,W$3<H70),F70*MIN(12,E70-(W$3-G70)*12)/E70,0)) -> 0 | X8: =IF(OR(D70=0,E70=0,F70=0),0,IF(AND(X$3>=G70,X$3<H70),F70*MIN(12,E70-(X$3-G70)*12)/E70,0)) -> 0 | Y8: =IF(OR(D70=0,E70=0,F70=0),0,IF(AND(Y$3>=G70,Y$3<H70),F70*MIN(12,E70-(Y$3-G70)*12)/E70,0)) -> 0 | Z8: =IF(OR(D70=0,E70=0,F70=0),0,IF(AND(Z$3>=G70,Z$3<H70),F70*MIN(12,E70-(Z$3-G70)*12)/E70,0)) -> 0 | AA8: =IF(OR(D70=0,E70=0,F70=0),0,IF(AND(AA$3>=G70,AA$3<H70),F70*MIN(12,E70-(AA$3-G70)*12)/E70,0)) -> 0 | AB8: =IF(OR(D70=0,E70=0,F70=0),0,IF(AND(AB$3>=G70,AB$3<H70),F70*MIN(12,E70-(AB$3-G70)*12)/E70,0)) -> 0 | AC8: =IF(OR(D70=0,E70=0,F70=0),0,IF(AND(AC$3>=G70,AC$3<H70),F70*MIN(12,E70-(AC$3-G70)*12)/E70,0)) -> 0 | AD8: =IF(OR(D70=0,E70=0,F70=0),0,IF(AND(AD$3>=G70,AD$3<H70),F70*MIN(12,E70-(AD$3-G70)*12)/E70,0)) -> 0 | AE8: =IF(OR(D70=0,E70=0,F70=0),0,IF(AND(AE$3>=G70,AE$3<H70),F70*MIN(12,E70-(AE$3-G70)*12)/E70,0)) -> 0 | AF8: =IF(OR(D70=0,E70=0,F70=0),0,IF(AND(AF$3>=G70,AF$3<H70),F70*MIN(12,E70-(AF$3-G70)*12)/E70,0)) -> 0 | AG8: =IF(OR(D70=0,E70=0,F70=0),0,IF(AND(AG$3>=G70,AG$3<H70),F70*MIN(12,E70-(AG$3-G70)*12)/E70,0)) -> 0 | AH8: =IF(OR(D70=0,E70=0,F70=0),0,IF(AND(AH$3>=G70,AH$3<H70),F70*MIN(12,E70-(AH$3-G70)*12)/E70,0)) -> 0 | AI8: =IF(OR(D70=0,E70=0,F70=0),0,IF(AND(AI$3>=G70,AI$3<H70),F70*MIN(12,E70-(AI$3-G70)*12)/E70,0)) -> 0 | AJ8: =IF(OR(D70=0,E70=0,F70=0),0,IF(AND(AJ$3>=G70,AJ$3<H70),F70*MIN(12,E70-(AJ$3-G70)*12)/E70,0)) -> 0 | AK8: =IF(OR(D70=0,E70=0,F70=0),0,IF(AND(AK$3>=G70,AK$3<H70),F70*MIN(12,E70-(AK$3-G70)*12)/E70,0)) -> 0 | AL8: =IF(OR(D70=0,E70=0,F70=0),0,IF(AND(AL$3>=G70,AL$3<H70),F70*MIN(12,E70-(AL$3-G70)*12)/E70,0)) -> 0 | AM8: =IF(OR(D70=0,E70=0,F70=0),0,IF(AND(AM$3>=G70,AM$3<H70),F70*MIN(12,E70-(AM$3-G70)*12)/E70,0)) -> 0 | AN8: =IF(OR(D70=0,E70=0,F70=0),0,IF(AND(AN$3>=G70,AN$3<H70),F70*MIN(12,E70-(AN$3-G70)*12)/E70,0)) -> 0 | AO8: =IF(OR(D70=0,E70=0,F70=0),0,IF(AND(AO$3>=G70,AO$3<H70),F70*MIN(12,E70-(AO$3-G70)*12)/E70,0)) -> 0 | AP8: =IF(OR(D70=0,E70=0,F70=0),0,IF(AND(AP$3>=G70,AP$3<H70),F70*MIN(12,E70-(AP$3-G70)*12)/E70,0)) -> 0 | AQ8: =IF(OR(D70=0,E70=0,F70=0),0,IF(AND(AQ$3>=G70,AQ$3<H70),F70*MIN(12,E70-(AQ$3-G70)*12)/E70,0)) -> 0 | AR8: =IF(OR(D70=0,E70=0,F70=0),0,IF(AND(AR$3>=G70,AR$3<H70),F70*MIN(12,E70-(AR$3-G70)*12)/E70,0)) -> 0 | AS8: =IF(OR(D70=0,E70=0,F70=0),0,IF(AND(AS$3>=G70,AS$3<H70),F70*MIN(12,E70-(AS$3-G70)*12)/E70,0)) -> 0 | AT8: =IF(OR(D70=0,E70=0,F70=0),0,IF(AND(AT$3>=G70,AT$3<H70),F70*MIN(12,E70-(AT$3-G70)*12)/E70,0)) -> 0 | AU8: =IF(OR(D70=0,E70=0,F70=0),0,IF(AND(AU$3>=G70,AU$3<H70),F70*MIN(12,E70-(AU$3-G70)*12)/E70,0)) -> 0 | AV8: =IF(OR(D70=0,E70=0,F70=0),0,IF(AND(AV$3>=G70,AV$3<H70),F70*MIN(12,E70-(AV$3-G70)*12)/E70,0)) -> 0 | AW8: =IF(OR(D70=0,E70=0,F70=0),0,IF(AND(AW$3>=G70,AW$3<H70),F70*MIN(12,E70-(AW$3-G70)*12)/E70,0)) -> 0 | AX8: =IF(OR(D70=0,E70=0,F70=0),0,IF(AND(AX$3>=G70,AX$3<H70),F70*MIN(12,E70-(AX$3-G70)*12)/E70,0)) -> 0 | AY8: =IF(OR(D70=0,E70=0,F70=0),0,IF(AND(AY$3>=G70,AY$3<H70),F70*MIN(12,E70-(AY$3-G70)*12)/E70,0)) -> 0 | AZ8: =IF(OR(D70=0,E70=0,F70=0),0,IF(AND(AZ$3>=G70,AZ$3<H70),F70*MIN(12,E70-(AZ$3-G70)*12)/E70,0)) -> 0 | BA8: =IF(OR(D70=0,E70=0,F70=0),0,IF(AND(BA$3>=G70,BA$3<H70),F70*MIN(12,E70-(BA$3-G70)*12)/E70,0)) -> 0 | BB8: =IF(OR(D70=0,E70=0,F70=0),0,IF(AND(BB$3>=G70,BB$3<H70),F70*MIN(12,E70-(BB$3-G70)*12)/E70,0)) -> 0
A9: =A71 -> 6 | B9: =B71 -> Marina Mall | C9: =C71 -> ZAN 1 | D9: =SUM(E9:BB9) -> 140810670 | E9: =IF(OR(D71=0,E71=0,F71=0),0,IF(AND(E$3>=G71,E$3<H71),F71*MIN(12,E71-(E$3-G71)*12)/E71,0)) -> 0 | F9: =IF(OR(D71=0,E71=0,F71=0),0,IF(AND(F$3>=G71,F$3<H71),F71*MIN(12,E71-(F$3-G71)*12)/E71,0)) -> 0 | G9: =IF(OR(D71=0,E71=0,F71=0),0,IF(AND(G$3>=G71,G$3<H71),F71*MIN(12,E71-(G$3-G71)*12)/E71,0)) -> 56324268 | H9: =IF(OR(D71=0,E71=0,F71=0),0,IF(AND(H$3>=G71,H$3<H71),F71*MIN(12,E71-(H$3-G71)*12)/E71,0)) -> 56324268 | I9: =IF(OR(D71=0,E71=0,F71=0),0,IF(AND(I$3>=G71,I$3<H71),F71*MIN(12,E71-(I$3-G71)*12)/E71,0)) -> 28162134 | J9: =IF(OR(D71=0,E71=0,F71=0),0,IF(AND(J$3>=G71,J$3<H71),F71*MIN(12,E71-(J$3-G71)*12)/E71,0)) -> 0 | K9: =IF(OR(D71=0,E71=0,F71=0),0,IF(AND(K$3>=G71,K$3<H71),F71*MIN(12,E71-(K$3-G71)*12)/E71,0)) -> 0 | L9: =IF(OR(D71=0,E71=0,F71=0),0,IF(AND(L$3>=G71,L$3<H71),F71*MIN(12,E71-(L$3-G71)*12)/E71,0)) -> 0 | M9: =IF(OR(D71=0,E71=0,F71=0),0,IF(AND(M$3>=G71,M$3<H71),F71*MIN(12,E71-(M$3-G71)*12)/E71,0)) -> 0 | N9: =IF(OR(D71=0,E71=0,F71=0),0,IF(AND(N$3>=G71,N$3<H71),F71*MIN(12,E71-(N$3-G71)*12)/E71,0)) -> 0 | O9: =IF(OR(D71=0,E71=0,F71=0),0,IF(AND(O$3>=G71,O$3<H71),F71*MIN(12,E71-(O$3-G71)*12)/E71,0)) -> 0 | P9: =IF(OR(D71=0,E71=0,F71=0),0,IF(AND(P$3>=G71,P$3<H71),F71*MIN(12,E71-(P$3-G71)*12)/E71,0)) -> 0 | Q9: =IF(OR(D71=0,E71=0,F71=0),0,IF(AND(Q$3>=G71,Q$3<H71),F71*MIN(12,E71-(Q$3-G71)*12)/E71,0)) -> 0 | R9: =IF(OR(D71=0,E71=0,F71=0),0,IF(AND(R$3>=G71,R$3<H71),F71*MIN(12,E71-(R$3-G71)*12)/E71,0)) -> 0 | S9: =IF(OR(D71=0,E71=0,F71=0),0,IF(AND(S$3>=G71,S$3<H71),F71*MIN(12,E71-(S$3-G71)*12)/E71,0)) -> 0 | T9: =IF(OR(D71=0,E71=0,F71=0),0,IF(AND(T$3>=G71,T$3<H71),F71*MIN(12,E71-(T$3-G71)*12)/E71,0)) -> 0 | U9: =IF(OR(D71=0,E71=0,F71=0),0,IF(AND(U$3>=G71,U$3<H71),F71*MIN(12,E71-(U$3-G71)*12)/E71,0)) -> 0 | V9: =IF(OR(D71=0,E71=0,F71=0),0,IF(AND(V$3>=G71,V$3<H71),F71*MIN(12,E71-(V$3-G71)*12)/E71,0)) -> 0 | W9: =IF(OR(D71=0,E71=0,F71=0),0,IF(AND(W$3>=G71,W$3<H71),F71*MIN(12,E71-(W$3-G71)*12)/E71,0)) -> 0 | X9: =IF(OR(D71=0,E71=0,F71=0),0,IF(AND(X$3>=G71,X$3<H71),F71*MIN(12,E71-(X$3-G71)*12)/E71,0)) -> 0 | Y9: =IF(OR(D71=0,E71=0,F71=0),0,IF(AND(Y$3>=G71,Y$3<H71),F71*MIN(12,E71-(Y$3-G71)*12)/E71,0)) -> 0 | Z9: =IF(OR(D71=0,E71=0,F71=0),0,IF(AND(Z$3>=G71,Z$3<H71),F71*MIN(12,E71-(Z$3-G71)*12)/E71,0)) -> 0 | AA9: =IF(OR(D71=0,E71=0,F71=0),0,IF(AND(AA$3>=G71,AA$3<H71),F71*MIN(12,E71-(AA$3-G71)*12)/E71,0)) -> 0 | AB9: =IF(OR(D71=0,E71=0,F71=0),0,IF(AND(AB$3>=G71,AB$3<H71),F71*MIN(12,E71-(AB$3-G71)*12)/E71,0)) -> 0 | AC9: =IF(OR(D71=0,E71=0,F71=0),0,IF(AND(AC$3>=G71,AC$3<H71),F71*MIN(12,E71-(AC$3-G71)*12)/E71,0)) -> 0 | AD9: =IF(OR(D71=0,E71=0,F71=0),0,IF(AND(AD$3>=G71,AD$3<H71),F71*MIN(12,E71-(AD$3-G71)*12)/E71,0)) -> 0 | AE9: =IF(OR(D71=0,E71=0,F71=0),0,IF(AND(AE$3>=G71,AE$3<H71),F71*MIN(12,E71-(AE$3-G71)*12)/E71,0)) -> 0 | AF9: =IF(OR(D71=0,E71=0,F71=0),0,IF(AND(AF$3>=G71,AF$3<H71),F71*MIN(12,E71-(AF$3-G71)*12)/E71,0)) -> 0 | AG9: =IF(OR(D71=0,E71=0,F71=0),0,IF(AND(AG$3>=G71,AG$3<H71),F71*MIN(12,E71-(AG$3-G71)*12)/E71,0)) -> 0 | AH9: =IF(OR(D71=0,E71=0,F71=0),0,IF(AND(AH$3>=G71,AH$3<H71),F71*MIN(12,E71-(AH$3-G71)*12)/E71,0)) -> 0 | AI9: =IF(OR(D71=0,E71=0,F71=0),0,IF(AND(AI$3>=G71,AI$3<H71),F71*MIN(12,E71-(AI$3-G71)*12)/E71,0)) -> 0 | AJ9: =IF(OR(D71=0,E71=0,F71=0),0,IF(AND(AJ$3>=G71,AJ$3<H71),F71*MIN(12,E71-(AJ$3-G71)*12)/E71,0)) -> 0 | AK9: =IF(OR(D71=0,E71=0,F71=0),0,IF(AND(AK$3>=G71,AK$3<H71),F71*MIN(12,E71-(AK$3-G71)*12)/E71,0)) -> 0 | AL9: =IF(OR(D71=0,E71=0,F71=0),0,IF(AND(AL$3>=G71,AL$3<H71),F71*MIN(12,E71-(AL$3-G71)*12)/E71,0)) -> 0 | AM9: =IF(OR(D71=0,E71=0,F71=0),0,IF(AND(AM$3>=G71,AM$3<H71),F71*MIN(12,E71-(AM$3-G71)*12)/E71,0)) -> 0 | AN9: =IF(OR(D71=0,E71=0,F71=0),0,IF(AND(AN$3>=G71,AN$3<H71),F71*MIN(12,E71-(AN$3-G71)*12)/E71,0)) -> 0 | AO9: =IF(OR(D71=0,E71=0,F71=0),0,IF(AND(AO$3>=G71,AO$3<H71),F71*MIN(12,E71-(AO$3-G71)*12)/E71,0)) -> 0 | AP9: =IF(OR(D71=0,E71=0,F71=0),0,IF(AND(AP$3>=G71,AP$3<H71),F71*MIN(12,E71-(AP$3-G71)*12)/E71,0)) -> 0 | AQ9: =IF(OR(D71=0,E71=0,F71=0),0,IF(AND(AQ$3>=G71,AQ$3<H71),F71*MIN(12,E71-(AQ$3-G71)*12)/E71,0)) -> 0 | AR9: =IF(OR(D71=0,E71=0,F71=0),0,IF(AND(AR$3>=G71,AR$3<H71),F71*MIN(12,E71-(AR$3-G71)*12)/E71,0)) -> 0 | AS9: =IF(OR(D71=0,E71=0,F71=0),0,IF(AND(AS$3>=G71,AS$3<H71),F71*MIN(12,E71-(AS$3-G71)*12)/E71,0)) -> 0 | AT9: =IF(OR(D71=0,E71=0,F71=0),0,IF(AND(AT$3>=G71,AT$3<H71),F71*MIN(12,E71-(AT$3-G71)*12)/E71,0)) -> 0 | AU9: =IF(OR(D71=0,E71=0,F71=0),0,IF(AND(AU$3>=G71,AU$3<H71),F71*MIN(12,E71-(AU$3-G71)*12)/E71,0)) -> 0 | AV9: =IF(OR(D71=0,E71=0,F71=0),0,IF(AND(AV$3>=G71,AV$3<H71),F71*MIN(12,E71-(AV$3-G71)*12)/E71,0)) -> 0 | AW9: =IF(OR(D71=0,E71=0,F71=0),0,IF(AND(AW$3>=G71,AW$3<H71),F71*MIN(12,E71-(AW$3-G71)*12)/E71,0)) -> 0 | AX9: =IF(OR(D71=0,E71=0,F71=0),0,IF(AND(AX$3>=G71,AX$3<H71),F71*MIN(12,E71-(AX$3-G71)*12)/E71,0)) -> 0 | AY9: =IF(OR(D71=0,E71=0,F71=0),0,IF(AND(AY$3>=G71,AY$3<H71),F71*MIN(12,E71-(AY$3-G71)*12)/E71,0)) -> 0 | AZ9: =IF(OR(D71=0,E71=0,F71=0),0,IF(AND(AZ$3>=G71,AZ$3<H71),F71*MIN(12,E71-(AZ$3-G71)*12)/E71,0)) -> 0 | BA9: =IF(OR(D71=0,E71=0,F71=0),0,IF(AND(BA$3>=G71,BA$3<H71),F71*MIN(12,E71-(BA$3-G71)*12)/E71,0)) -> 0 | BB9: =IF(OR(D71=0,E71=0,F71=0),0,IF(AND(BB$3>=G71,BB$3<H71),F71*MIN(12,E71-(BB$3-G71)*12)/E71,0)) -> 0
A10: =A72 -> 7 | B10: =B72 -> Seafront Mall | C10: =C72 -> ZAN 2 | D10: =SUM(E10:BB10) -> 36051015 | E10: =IF(OR(D72=0,E72=0,F72=0),0,IF(AND(E$3>=G72,E$3<H72),F72*MIN(12,E72-(E$3-G72)*12)/E72,0)) -> 0 | F10: =IF(OR(D72=0,E72=0,F72=0),0,IF(AND(F$3>=G72,F$3<H72),F72*MIN(12,E72-(F$3-G72)*12)/E72,0)) -> 0 | G10: =IF(OR(D72=0,E72=0,F72=0),0,IF(AND(G$3>=G72,G$3<H72),F72*MIN(12,E72-(G$3-G72)*12)/E72,0)) -> 0 | H10: =IF(OR(D72=0,E72=0,F72=0),0,IF(AND(H$3>=G72,H$3<H72),F72*MIN(12,E72-(H$3-G72)*12)/E72,0)) -> 18025508 | I10: =IF(OR(D72=0,E72=0,F72=0),0,IF(AND(I$3>=G72,I$3<H72),F72*MIN(12,E72-(I$3-G72)*12)/E72,0)) -> 18025508 | J10: =IF(OR(D72=0,E72=0,F72=0),0,IF(AND(J$3>=G72,J$3<H72),F72*MIN(12,E72-(J$3-G72)*12)/E72,0)) -> 0 | K10: =IF(OR(D72=0,E72=0,F72=0),0,IF(AND(K$3>=G72,K$3<H72),F72*MIN(12,E72-(K$3-G72)*12)/E72,0)) -> 0 | L10: =IF(OR(D72=0,E72=0,F72=0),0,IF(AND(L$3>=G72,L$3<H72),F72*MIN(12,E72-(L$3-G72)*12)/E72,0)) -> 0 | M10: =IF(OR(D72=0,E72=0,F72=0),0,IF(AND(M$3>=G72,M$3<H72),F72*MIN(12,E72-(M$3-G72)*12)/E72,0)) -> 0 | N10: =IF(OR(D72=0,E72=0,F72=0),0,IF(AND(N$3>=G72,N$3<H72),F72*MIN(12,E72-(N$3-G72)*12)/E72,0)) -> 0 | O10: =IF(OR(D72=0,E72=0,F72=0),0,IF(AND(O$3>=G72,O$3<H72),F72*MIN(12,E72-(O$3-G72)*12)/E72,0)) -> 0 | P10: =IF(OR(D72=0,E72=0,F72=0),0,IF(AND(P$3>=G72,P$3<H72),F72*MIN(12,E72-(P$3-G72)*12)/E72,0)) -> 0 | Q10: =IF(OR(D72=0,E72=0,F72=0),0,IF(AND(Q$3>=G72,Q$3<H72),F72*MIN(12,E72-(Q$3-G72)*12)/E72,0)) -> 0 | R10: =IF(OR(D72=0,E72=0,F72=0),0,IF(AND(R$3>=G72,R$3<H72),F72*MIN(12,E72-(R$3-G72)*12)/E72,0)) -> 0 | S10: =IF(OR(D72=0,E72=0,F72=0),0,IF(AND(S$3>=G72,S$3<H72),F72*MIN(12,E72-(S$3-G72)*12)/E72,0)) -> 0 | T10: =IF(OR(D72=0,E72=0,F72=0),0,IF(AND(T$3>=G72,T$3<H72),F72*MIN(12,E72-(T$3-G72)*12)/E72,0)) -> 0 | U10: =IF(OR(D72=0,E72=0,F72=0),0,IF(AND(U$3>=G72,U$3<H72),F72*MIN(12,E72-(U$3-G72)*12)/E72,0)) -> 0 | V10: =IF(OR(D72=0,E72=0,F72=0),0,IF(AND(V$3>=G72,V$3<H72),F72*MIN(12,E72-(V$3-G72)*12)/E72,0)) -> 0 | W10: =IF(OR(D72=0,E72=0,F72=0),0,IF(AND(W$3>=G72,W$3<H72),F72*MIN(12,E72-(W$3-G72)*12)/E72,0)) -> 0 | X10: =IF(OR(D72=0,E72=0,F72=0),0,IF(AND(X$3>=G72,X$3<H72),F72*MIN(12,E72-(X$3-G72)*12)/E72,0)) -> 0 | Y10: =IF(OR(D72=0,E72=0,F72=0),0,IF(AND(Y$3>=G72,Y$3<H72),F72*MIN(12,E72-(Y$3-G72)*12)/E72,0)) -> 0 | Z10: =IF(OR(D72=0,E72=0,F72=0),0,IF(AND(Z$3>=G72,Z$3<H72),F72*MIN(12,E72-(Z$3-G72)*12)/E72,0)) -> 0 | AA10: =IF(OR(D72=0,E72=0,F72=0),0,IF(AND(AA$3>=G72,AA$3<H72),F72*MIN(12,E72-(AA$3-G72)*12)/E72,0)) -> 0 | AB10: =IF(OR(D72=0,E72=0,F72=0),0,IF(AND(AB$3>=G72,AB$3<H72),F72*MIN(12,E72-(AB$3-G72)*12)/E72,0)) -> 0 | AC10: =IF(OR(D72=0,E72=0,F72=0),0,IF(AND(AC$3>=G72,AC$3<H72),F72*MIN(12,E72-(AC$3-G72)*12)/E72,0)) -> 0 | AD10: =IF(OR(D72=0,E72=0,F72=0),0,IF(AND(AD$3>=G72,AD$3<H72),F72*MIN(12,E72-(AD$3-G72)*12)/E72,0)) -> 0 | AE10: =IF(OR(D72=0,E72=0,F72=0),0,IF(AND(AE$3>=G72,AE$3<H72),F72*MIN(12,E72-(AE$3-G72)*12)/E72,0)) -> 0 | AF10: =IF(OR(D72=0,E72=0,F72=0),0,IF(AND(AF$3>=G72,AF$3<H72),F72*MIN(12,E72-(AF$3-G72)*12)/E72,0)) -> 0 | AG10: =IF(OR(D72=0,E72=0,F72=0),0,IF(AND(AG$3>=G72,AG$3<H72),F72*MIN(12,E72-(AG$3-G72)*12)/E72,0)) -> 0 | AH10: =IF(OR(D72=0,E72=0,F72=0),0,IF(AND(AH$3>=G72,AH$3<H72),F72*MIN(12,E72-(AH$3-G72)*12)/E72,0)) -> 0 | AI10: =IF(OR(D72=0,E72=0,F72=0),0,IF(AND(AI$3>=G72,AI$3<H72),F72*MIN(12,E72-(AI$3-G72)*12)/E72,0)) -> 0 | AJ10: =IF(OR(D72=0,E72=0,F72=0),0,IF(AND(AJ$3>=G72,AJ$3<H72),F72*MIN(12,E72-(AJ$3-G72)*12)/E72,0)) -> 0 | AK10: =IF(OR(D72=0,E72=0,F72=0),0,IF(AND(AK$3>=G72,AK$3<H72),F72*MIN(12,E72-(AK$3-G72)*12)/E72,0)) -> 0 | AL10: =IF(OR(D72=0,E72=0,F72=0),0,IF(AND(AL$3>=G72,AL$3<H72),F72*MIN(12,E72-(AL$3-G72)*12)/E72,0)) -> 0 | AM10: =IF(OR(D72=0,E72=0,F72=0),0,IF(AND(AM$3>=G72,AM$3<H72),F72*MIN(12,E72-(AM$3-G72)*12)/E72,0)) -> 0 | AN10: =IF(OR(D72=0,E72=0,F72=0),0,IF(AND(AN$3>=G72,AN$3<H72),F72*MIN(12,E72-(AN$3-G72)*12)/E72,0)) -> 0 | AO10: =IF(OR(D72=0,E72=0,F72=0),0,IF(AND(AO$3>=G72,AO$3<H72),F72*MIN(12,E72-(AO$3-G72)*12)/E72,0)) -> 0 | AP10: =IF(OR(D72=0,E72=0,F72=0),0,IF(AND(AP$3>=G72,AP$3<H72),F72*MIN(12,E72-(AP$3-G72)*12)/E72,0)) -> 0 | AQ10: =IF(OR(D72=0,E72=0,F72=0),0,IF(AND(AQ$3>=G72,AQ$3<H72),F72*MIN(12,E72-(AQ$3-G72)*12)/E72,0)) -> 0 | AR10: =IF(OR(D72=0,E72=0,F72=0),0,IF(AND(AR$3>=G72,AR$3<H72),F72*MIN(12,E72-(AR$3-G72)*12)/E72,0)) -> 0 | AS10: =IF(OR(D72=0,E72=0,F72=0),0,IF(AND(AS$3>=G72,AS$3<H72),F72*MIN(12,E72-(AS$3-G72)*12)/E72,0)) -> 0 | AT10: =IF(OR(D72=0,E72=0,F72=0),0,IF(AND(AT$3>=G72,AT$3<H72),F72*MIN(12,E72-(AT$3-G72)*12)/E72,0)) -> 0 | AU10: =IF(OR(D72=0,E72=0,F72=0),0,IF(AND(AU$3>=G72,AU$3<H72),F72*MIN(12,E72-(AU$3-G72)*12)/E72,0)) -> 0 | AV10: =IF(OR(D72=0,E72=0,F72=0),0,IF(AND(AV$3>=G72,AV$3<H72),F72*MIN(12,E72-(AV$3-G72)*12)/E72,0)) -> 0 | AW10: =IF(OR(D72=0,E72=0,F72=0),0,IF(AND(AW$3>=G72,AW$3<H72),F72*MIN(12,E72-(AW$3-G72)*12)/E72,0)) -> 0 | AX10: =IF(OR(D72=0,E72=0,F72=0),0,IF(AND(AX$3>=G72,AX$3<H72),F72*MIN(12,E72-(AX$3-G72)*12)/E72,0)) -> 0 | AY10: =IF(OR(D72=0,E72=0,F72=0),0,IF(AND(AY$3>=G72,AY$3<H72),F72*MIN(12,E72-(AY$3-G72)*12)/E72,0)) -> 0 | AZ10: =IF(OR(D72=0,E72=0,F72=0),0,IF(AND(AZ$3>=G72,AZ$3<H72),F72*MIN(12,E72-(AZ$3-G72)*12)/E72,0)) -> 0 | BA10: =IF(OR(D72=0,E72=0,F72=0),0,IF(AND(BA$3>=G72,BA$3<H72),F72*MIN(12,E72-(BA$3-G72)*12)/E72,0)) -> 0 | BB10: =IF(OR(D72=0,E72=0,F72=0),0,IF(AND(BB$3>=G72,BB$3<H72),F72*MIN(12,E72-(BB$3-G72)*12)/E72,0)) -> 0
